Workbook

Sheet Price summary
A1: DKV SWEDEN MAY 2026 - JUPITER PLUS AS - NET PRICE OVERVIEW (SEK excl. 25% VAT, after DKV discount)
A2: Invoices 26/651689595/011 (1-15 May, due per DKV terms) + 26/652169828/011 (16-31 May); payable in EUR
A4: Diesel by station (city) | B4: Litres | C4: Net SEK after disc | D4: Eff. net SEK/L | E4: approx EUR/L @10.80 | F4: Discount SEK/L
A5: TANUMSHEDE | B5: =SUMPRODUCT((Transactions!$F$2:$F$86=A5)*(Transactions!$G$2:$G$86="DIESEL")*Transactions!$H$2:$H$86) -> 2131.12 | C5: =ROUND(SUMPRODUCT((Transactions!$F$2:$F$86=A5)*(Transactions!$G$2:$G$86="DIESEL")*Transactions!$N$2:$N$86),2) -> 33242.91 | D5: =C5/B5 -> 15.598798 | E5: =D5/10.8 -> 1.4443331 | F5: =-ROUND(SUMPRODUCT((Transactions!$F$2:$F$86=A5)*(Transactions!$G$2:$G$86="DIESEL")*Transactions!$L$2:$L$86),2)/B5 -> 1.2999972
A6: FALKENBERG | B6: =SUMPRODUCT((Transactions!$F$2:$F$86=A6)*(Transactions!$G$2:$G$86="DIESEL")*Transactions!$H$2:$H$86) -> 1475.77 | C6: =ROUND(SUMPRODUCT((Transactions!$F$2:$F$86=A6)*(Transactions!$G$2:$G$86="DIESEL")*Transactions!$N$2:$N$86),2) -> 23250.42 | D6: =C6/B6 -> 15.754772 | E6: =D6/10.8 -> 1.4587752 | F6: =-ROUND(SUMPRODUCT((Transactions!$F$2:$F$86=A6)*(Transactions!$G$2:$G$86="DIESEL")*Transactions!$L$2:$L$86),2)/B6 -> 1.3000061
A7: TRELLEBORG | B7: =SUMPRODUCT((Transactions!$F$2:$F$86=A7)*(Transactions!$G$2:$G$86="DIESEL")*Transactions!$H$2:$H$86) -> 1530.35 | C7: =ROUND(SUMPRODUCT((Transactions!$F$2:$F$86=A7)*(Transactions!$G$2:$G$86="DIESEL")*Transactions!$N$2:$N$86),2) -> 24506.81 | D7: =C7/B7 -> 16.01386 | E7: =D7/10.8 -> 1.4827648 | F7: =-ROUND(SUMPRODUCT((Transactions!$F$2:$F$86=A7)*(Transactions!$G$2:$G$86="DIESEL")*Transactions!$L$2:$L$86),2)/B7 -> 1.3000033
A8: HELSINGBORG | B8: =SUMPRODUCT((Transactions!$F$2:$F$86=A8)*(Transactions!$G$2:$G$86="DIESEL")*Transactions!$H$2:$H$86) -> 930.45 | C8: =ROUND(SUMPRODUCT((Transactions!$F$2:$F$86=A8)*(Transactions!$G$2:$G$86="DIESEL")*Transactions!$N$2:$N$86),2) -> 14771.83 | D8: =C8/B8 -> 15.876006 | E8: =D8/10.8 -> 1.4700006 | F8: =-ROUND(SUMPRODUCT((Transactions!$F$2:$F$86=A8)*(Transactions!$G$2:$G$86="DIESEL")*Transactions!$L$2:$L$86),2)/B8 -> 1.2999946
A9: BASTAD | B9: =SUMPRODUCT((Transactions!$F$2:$F$86=A9)*(Transactions!$G$2:$G$86="DIESEL")*Transactions!$H$2:$H$86) -> 1514.2 | C9: =ROUND(SUMPRODUCT((Transactions!$F$2:$F$86=A9)*(Transactions!$G$2:$G$86="DIESEL")*Transactions!$N$2:$N$86),2) -> 24368.72 | D9: =C9/B9 -> 16.093462 | E9: =D9/10.8 -> 1.4901354 | F9: =-ROUND(SUMPRODUCT((Transactions!$F$2:$F$86=A9)*(Transactions!$G$2:$G$86="DIESEL")*Transactions!$L$2:$L$86),2)/B9 -> 1.3000066
A10: MARKARYD | B10: =SUMPRODUCT((Transactions!$F$2:$F$86=A10)*(Transactions!$G$2:$G$86="DIESEL")*Transactions!$H$2:$H$86) -> 1452.84 | C10: =ROUND(SUMPRODUCT((Transactions!$F$2:$F$86=A10)*(Transactions!$G$2:$G$86="DIESEL")*Transactions!$N$2:$N$86),2) -> 23169.21 | D10: =C10/B10 -> 15.94753 | E10: =D10/10.8 -> 1.4766232 | F10: =-ROUND(SUMPRODUCT((Transactions!$F$2:$F$86=A10)*(Transactions!$G$2:$G$86="DIESEL")*Transactions!$L$2:$L$86),2)/B10 -> 1.2999986
A11: ARLOV | B11: =SUMPRODUCT((Transactions!$F$2:$F$86=A11)*(Transactions!$G$2:$G$86="DIESEL")*Transactions!$H$2:$H$86) -> 1131.68 | C11: =ROUND(SUMPRODUCT((Transactions!$F$2:$F$86=A11)*(Transactions!$G$2:$G$86="DIESEL")*Transactions!$N$2:$N$86),2) -> 17966.54 | D11: =C11/B11 -> 15.87599 | E11: =D11/10.8 -> 1.469999 | F11: =-ROUND(SUMPRODUCT((Transactions!$F$2:$F$86=A11)*(Transactions!$G$2:$G$86="DIESEL")*Transactions!$L$2:$L$86),2)/B11 -> 1.3000053
A12: LANDSKRONA | B12: =SUMPRODUCT((Transactions!$F$2:$F$86=A12)*(Transactions!$G$2:$G$86="DIESEL")*Transactions!$H$2:$H$86) -> 1121 | C12: =ROUND(SUMPRODUCT((Transactions!$F$2:$F$86=A12)*(Transactions!$G$2:$G$86="DIESEL")*Transactions!$N$2:$N$86),2) -> 17666.82 | D12: =C12/B12 -> 15.759875 | E12: =D12/10.8 -> 1.4592477 | F12: =-ROUND(SUMPRODUCT((Transactions!$F$2:$F$86=A12)*(Transactions!$G$2:$G$86="DIESEL")*Transactions!$L$2:$L$86),2)/B12 -> 1.3
A13: GOTEBORG | B13: =SUMPRODUCT((Transactions!$F$2:$F$86=A13)*(Transactions!$G$2:$G$86="DIESEL")*Transactions!$H$2:$H$86) -> 1181.01 | C13: =ROUND(SUMPRODUCT((Transactions!$F$2:$F$86=A13)*(Transactions!$G$2:$G$86="DIESEL")*Transactions!$N$2:$N$86),2) -> 18935.18 | D13: =C13/B13 -> 16.03304 | E13: =D13/10.8 -> 1.4845407 | F13: =-ROUND(SUMPRODUCT((Transactions!$F$2:$F$86=A13)*(Transactions!$G$2:$G$86="DIESEL")*Transactions!$L$2:$L$86),2)/B13 -> 1.2999975
A14: HALMSTAD | B14: =SUMPRODUCT((Transactions!$F$2:$F$86=A14)*(Transactions!$G$2:$G$86="DIESEL")*Transactions!$H$2:$H$86) -> 478.93 | C14: =ROUND(SUMPRODUCT((Transactions!$F$2:$F$86=A14)*(Transactions!$G$2:$G$86="DIESEL")*Transactions!$N$2:$N$86),2) -> 7603.49 | D14: =C14/B14 -> 15.875994 | E14: =D14/10.8 -> 1.4699995 | F14: =-ROUND(SUMPRODUCT((Transactions!$F$2:$F$86=A14)*(Transactions!$G$2:$G$86="DIESEL")*Transactions!$L$2:$L$86),2)/B14 -> 1.3000021
A15: LILLA EDET | B15: =SUMPRODUCT((Transactions!$F$2:$F$86=A15)*(Transactions!$G$2:$G$86="DIESEL")*Transactions!$H$2:$H$86) -> 836.1 | C15: =ROUND(SUMPRODUCT((Transactions!$F$2:$F$86=A15)*(Transactions!$G$2:$G$86="DIESEL")*Transactions!$N$2:$N$86),2) -> 13628.43 | D15: =C15/B15 -> 16.3 | E15: =D15/10.8 -> 1.5092593 | F15: =-ROUND(SUMPRODUCT((Transactions!$F$2:$F$86=A15)*(Transactions!$G$2:$G$86="DIESEL")*Transactions!$L$2:$L$86),2)/B15 -> 1.3
A16: ANGELHOLM | B16: =SUMPRODUCT((Transactions!$F$2:$F$86=A16)*(Transactions!$G$2:$G$86="DIESEL")*Transactions!$H$2:$H$86) -> 665.98 | C16: =ROUND(SUMPRODUCT((Transactions!$F$2:$F$86=A16)*(Transactions!$G$2:$G$86="DIESEL")*Transactions!$N$2:$N$86),2) -> 10562.43 | D16: =C16/B16 -> 15.859981 | E16: =D16/10.8 -> 1.4685167 | F16: =-ROUND(SUMPRODUCT((Transactions!$F$2:$F$86=A16)*(Transactions!$G$2:$G$86="DIESEL")*Transactions!$L$2:$L$86),2)/B16 -> 1.300009
... A23: HISINGS BACKA | B23: =SUMPRODUCT((Transactions!$F$2:$F$86=A23)*(Transactions!$G$2:$G$86="DIESEL")*Transactions!$H$2:$H$86) -> 400.03 | C23: =ROUND(SUMPRODUCT((Transactions!$F$2:$F$86=A23)*(Transactions!$G$2:$G$86="DIESEL")*Transactions!$N$2:$N$86),2) -> 6520.49 | D23: =C23/B23 -> 16.300002 | E23: =D23/10.8 -> 1.5092595 | F23: =-ROUND(SUMPRODUCT((Transactions!$F$2:$F$86=A23)*(Transactions!$G$2:$G$86="DIESEL")*Transactions!$L$2:$L$86),2)/B23 -> 1.3000025
A24: TOTAL DIESEL | B24: =SUM(B5:B23) -> 17331.88 | C24: =SUM(C5:C23) -> 276106.59 | D24: =C24/B24 -> 15.930562 | E24: =D24/10.8 -> 1.475052 | F24: =-SUMPRODUCT((Transactions!$G$2:$G$86="DIESEL")*Transactions!$L$2:$L$86)/B24 -> 1.3000015
A26: By half-month (diesel) | B26: Litres | C26: Net SEK | D26: Eff. net SEK/L | E26: approx EUR/L
A27: 01-15 May | B27: =SUMPRODUCT((Transactions!$A$2:$A$86="26/651689595")*(Transactions!$G$2:$G$86="DIESEL")*Transactions!$H$2:$H$86) -> 10407.49 | C27: =ROUND(SUMPRODUCT((Transactions!$A$2:$A$86="26/651689595")*(Transactions!$G$2:$G$86="DIESEL")*Transactions!$N$2:$N$86),2) -> 166997.74 | D27: =C27/B27 -> 16.045919 | E27: =D27/10.8 -> 1.4857332
A28: 16-31 May | B28: =SUMPRODUCT((Transactions!$A$2:$A$86="26/652169828")*(Transactions!$G$2:$G$86="DIESEL")*Transactions!$H$2:$H$86) -> 6924.39 | C28: =ROUND(SUMPRODUCT((Transactions!$A$2:$A$86="26/652169828")*(Transactions!$G$2:$G$86="DIESEL")*Transactions!$N$2:$N$86),2) -> 109108.85 | D28: =C28/B28 -> 15.757179 | E28: =D28/10.8 -> 1.458998
A30: Other products | B30: Qty | C30: Net SEK | D30: Eff. net SEK/unit | E30: approx EUR/unit
A31: AdBlue (bulk), L | B31: =SUMPRODUCT((Transactions!$G$2:$G$86="ADBLUE")*Transactions!$H$2:$H$86) -> 754.31 | C31: =ROUND(SUMPRODUCT((Transactions!$G$2:$G$86="ADBLUE")*Transactions!$N$2:$N$86),2) -> 5139.68 | D31: =C31/B31 -> 6.8137503 | E31: =D31/10.8 -> 0.63090281
A32: HVO 100 renewable diesel, L | B32: =SUMPRODUCT((Transactions!$G$2:$G$86="HVO 100")*Transactions!$H$2:$H$86) -> 251 | C32: =ROUND(SUMPRODUCT((Transactions!$G$2:$G$86="HVO 100")*Transactions!$N$2:$N$86),2) -> 5732.34 | D32: =C32/B32 -> 22.838008 | E32: =D32/10.8 -> 2.1146304
A33: Parking services, pc | B33: =SUMPRODUCT((Transactions!$G$2:$G$86="parking")*Transactions!$H$2:$H$86) -> 11 | C33: =ROUND(SUMPRODUCT((Transactions!$G$2:$G$86="parking")*Transactions!$N$2:$N$86),2) -> 2957.53 | D33: =C33/B33 -> 268.86636 | E33: =D33/10.8 -> 24.895034
A35: EUR/L shown at indicative 10.80 SEK/EUR (DKV converts per transaction date; implied invoice rates 10.82 and 10.78). Swedish VAT 25% is charged on top and reclaimable via EE registration. Pump net prices fell 17.60 -> 16.856 -> 17.16 SEK/L over the month; DKV discount averages ~1.3 SEK/L net.

Sheet Transactions
A1: Invoice | B1: Vehicle | C1: Date | D1: Time | E1: Brand | F1: City | G1: Product | H1: Qty (L/pc) | I1: Gross SEK/unit | J1: Net SEK/unit | K1: Base net SEK | L1: Discount net SEK | M1: Service fee net SEK | N1: Total net SEK | O1: VAT 25% SEK | P1: Total gross SEK | Q1: Payable EUR | R1: Eff. net SEK/L after disc | S1: Chk1: base=qty x net | T1: Chk2: net=base+disc+fee | U1: Chk3: VAT=25% | V1: Chk4: gross=net+VAT
A2: 26/651689595 | B2: 009 | C2: 2026-05-04 | D2: 19:46 | E2: CIRCLE K | F2: GOETEBORG | G2: parking | H2: 1 | I2: 295 | J2: 236 | K2: 236 | L2: 0 | M2: 13.28 | N2: 249.28 | O2: 62.32 | P2: 311.6 | Q2: 28.85 | R2: =IF(G2="parking","",(K2+L2)/H2) | S2: =IF(ABS(ROUND(H2*J2,2)-K2)<=0.02,"OK","CHECK") -> OK | T2: =IF(ABS(ROUND(K2+L2+IF(M2="",0,M2),2)-N2)<=0.011,"OK","CHECK") -> OK | U2: =IF(ABS(ROUND(N2*0.25,2)-O2)<=0.07,"OK","CHECK") -> OK | V2: =IF(ABS(N2+O2-P2)<=0.011,"OK","CHECK") -> OK
A3: 26/651689595 | B3: 009 | C3: 2026-05-05 | D3: 08:53 | E3: PREEM | F3: HISINGS BACKA | G3: DIESEL | H3: 250 | I3: 22 | J3: 17.6 | K3: 4400 | L3: -325 | N3: 4075 | O3: 1018.75 | P3: 5093.75 | Q3: 471.37 | R3: =IF(G3="parking","",(K3+L3)/H3) -> 16.3 | S3: =IF(ABS(ROUND(H3*J3,2)-K3)<=0.02,"OK","CHECK") -> OK | T3: =IF(ABS(ROUND(K3+L3+IF(M3="",0,M3),2)-N3)<=0.011,"OK","CHECK") -> OK | U3: =IF(ABS(ROUND(N3*0.25,2)-O3)<=0.07,"OK","CHECK") -> OK | V3: =IF(ABS(N3+O3-P3)<=0.011,"OK","CHECK") -> OK
A4: 26/651689595 | B4: 009 | C4: 2026-05-05 | D4: 08:59 | E4: PREEM | F4: HISINGS BACKA | G4: DIESEL | H4: 150.03 | I4: 22 | J4: 17.6 | K4: 2640.53 | L4: -195.04 | N4: 2445.49 | O4: 611.37 | P4: 3056.86 | Q4: 282.88 | R4: =IF(G4="parking","",(K4+L4)/H4) -> 16.300007 | S4: =IF(ABS(ROUND(H4*J4,2)-K4)<=0.02,"OK","CHECK") -> OK | T4: =IF(ABS(ROUND(K4+L4+IF(M4="",0,M4),2)-N4)<=0.011,"OK","CHECK") -> OK | U4: =IF(ABS(ROUND(N4*0.25,2)-O4)<=0.07,"OK","CHECK") -> OK | V4: =IF(ABS(N4+O4-P4)<=0.011,"OK","CHECK") -> OK
A5: 26/651689595 | B5: 018 | C5: 2026-05-05 | D5: 21:43 | E5: CIRCLE K | F5: GOETEBORG | G5: parking | H5: 1 | I5: 295 | J5: 236 | K5: 236 | L5: 0 | M5: 13.28 | N5: 249.28 | O5: 62.32 | P5: 311.6 | Q5: 28.83 | R5: =IF(G5="parking","",(K5+L5)/H5) | S5: =IF(ABS(ROUND(H5*J5,2)-K5)<=0.02,"OK","CHECK") -> OK | T5: =IF(ABS(ROUND(K5+L5+IF(M5="",0,M5),2)-N5)<=0.011,"OK","CHECK") -> OK | U5: =IF(ABS(ROUND(N5*0.25,2)-O5)<=0.07,"OK","CHECK") -> OK | V5: =IF(ABS(N5+O5-P5)<=0.011,"OK","CHECK") -> OK
A6: 26/651689595 | B6: 022 | C6: 2026-05-08 | D6: 10:53 | E6: PREEM | F6: LILLA EDET | G6: DIESEL | H6: 409.09 | I6: 22 | J6: 17.6 | K6: 7199.98 | L6: -531.82 | N6: 6668.16 | O6: 1667.04 | P6: 8335.2 | Q6: 772.65 | R6: =IF(G6="parking","",(K6+L6)/H6) -> 16.299983 | S6: =IF(ABS(ROUND(H6*J6,2)-K6)<=0.02,"OK","CHECK") -> OK | T6: =IF(ABS(ROUND(K6+L6+IF(M6="",0,M6),2)-N6)<=0.011,"OK","CHECK") -> OK | U6: =IF(ABS(ROUND(N6*0.25,2)-O6)<=0.07,"OK","CHECK") -> OK | V6: =IF(ABS(N6+O6-P6)<=0.011,"OK","CHECK") -> OK
A7: 26/651689595 | B7: 022 | C7: 2026-05-08 | D7: 11:00 | E7: PREEM | F7: LILLA EDET | G7: DIESEL | H7: 121.01 | I7: 22 | J7: 17.6 | K7: 2129.78 | L7: -157.31 | N7: 1972.47 | O7: 493.12 | P7: 2465.59 | Q7: 228.55 | R7: =IF(G7="parking","",(K7+L7)/H7) -> 16.300058 | S7: =IF(ABS(ROUND(H7*J7,2)-K7)<=0.02,"OK","CHECK") -> OK | T7: =IF(ABS(ROUND(K7+L7+IF(M7="",0,M7),2)-N7)<=0.011,"OK","CHECK") -> OK | U7: =IF(ABS(ROUND(N7*0.25,2)-O7)<=0.07,"OK","CHECK") -> OK | V7: =IF(ABS(N7+O7-P7)<=0.011,"OK","CHECK") -> OK
A8: 26/651689595 | B8: 022 | C8: 2026-05-08 | D8: 11:04 | E8: PREEM | F8: LILLA EDET | G8: DIESEL | H8: 306 | I8: 22 | J8: 17.6 | K8: 5385.6 | L8: -397.8 | N8: 4987.8 | O8: 1246.95 | P8: 6234.75 | Q8: 577.94 | R8: =IF(G8="parking","",(K8+L8)/H8) -> 16.3 | S8: =IF(ABS(ROUND(H8*J8,2)-K8)<=0.02,"OK","CHECK") -> OK | T8: =IF(ABS(ROUND(K8+L8+IF(M8="",0,M8),2)-N8)<=0.011,"OK","CHECK") -> OK | U8: =IF(ABS(ROUND(N8*0.25,2)-O8)<=0.07,"OK","CHECK") -> OK | V8: =IF(ABS(N8+O8-P8)<=0.011,"OK","CHECK") -> OK
A9: 26/651689595 | B9: 022 | C9: 2026-05-08 | D9: 11:12 | E9: PREEM | F9: LILLA EDET | G9: ADBLUE | H9: 17.32 | I9: 10.3897 | J9: 8.3118 | K9: 143.96 | L9: -21.13 | N9: 122.83 | O9: 30.71 | P9: 153.54 | Q9: 14.24 | R9: =IF(G9="parking","",(K9+L9)/H9) -> 7.0918014 | S9: =IF(ABS(ROUND(H9*J9,2)-K9)<=0.02,"OK","CHECK") -> OK | T9: =IF(ABS(ROUND(K9+L9+IF(M9="",0,M9),2)-N9)<=0.011,"OK","CHECK") -> OK | U9: =IF(ABS(ROUND(N9*0.25,2)-O9)<=0.07,"OK","CHECK") -> OK | V9: =IF(ABS(N9+O9-P9)<=0.011,"OK","CHECK") -> OK
A10: 26/651689595 | B10: 025 | C10: 2026-05-11 | D10: 17:51 | E10: PREEM | F10: KVANUM | G10: DIESEL | H10: 470.53 | I10: 21.47 | J10: 17.176 | K10: 8081.82 | L10: -611.69 | N10: 7470.13 | O10: 1867.53 | P10: 9337.66 | Q10: 862.03 | R10: =IF(G10="parking","",(K10+L10)/H10) -> 15.875991 | S10: =IF(ABS(ROUND(H10*J10,2)-K10)<=0.02,"OK","CHECK") -> OK | T10: =IF(ABS(ROUND(K10+L10+IF(M10="",0,M10),2)-N10)<=0.011,"OK","CHECK") -> OK | U10: =IF(ABS(ROUND(N10*0.25,2)-O10)<=0.07,"OK","CHECK") -> OK | V10: =IF(ABS(N10+O10-P10)<=0.011,"OK","CHECK") -> OK
A11: 26/651689595 | B11: 025 | C11: 2026-05-11 | D11: 18:02 | E11: PREEM | F11: KVANUM | G11: ADBLUE | H11: 55.06 | I11: 9.8899 | J11: 7.9119 | K11: 435.63 | L11: -67.17 | N11: 368.46 | O11: 92.12 | P11: 460.58 | Q11: 42.52 | R11: =IF(G11="parking","",(K11+L11)/H11) -> 6.6919724 | S11: =IF(ABS(ROUND(H11*J11,2)-K11)<=0.02,"OK","CHECK") -> OK | T11: =IF(ABS(ROUND(K11+L11+IF(M11="",0,M11),2)-N11)<=0.011,"OK","CHECK") -> OK | U11: =IF(ABS(ROUND(N11*0.25,2)-O11)<=0.07,"OK","CHECK") -> OK | V11: =IF(ABS(N11+O11-P11)<=0.011,"OK","CHECK") -> OK
A12: 26/651689595 | B12: 025 | C12: 2026-05-14 | D12: 19:30 | E12: CIRCLE K | F12: GOETEBORG | G12: parking | H12: 1 | I12: 295 | J12: 236 | K12: 236 | L12: 0 | M12: 13.28 | N12: 249.28 | O12: 62.32 | P12: 311.6 | Q12: 28.66 | R12: =IF(G12="parking","",(K12+L12)/H12) | S12: =IF(ABS(ROUND(H12*J12,2)-K12)<=0.02,"OK","CHECK") -> OK | T12: =IF(ABS(ROUND(K12+L12+IF(M12="",0,M12),2)-N12)<=0.011,"OK","CHECK") -> OK | U12: =IF(ABS(ROUND(N12*0.25,2)-O12)<=0.07,"OK","CHECK") -> OK | V12: =IF(ABS(N12+O12-P12)<=0.011,"OK","CHECK") -> OK
A13: 26/651689595 | B13: 025 | C13: 2026-05-15 | D13: 16:40 | E13: PREEM | F13: ARLOV | G13: DIESEL | H13: 419.19 | I13: 21.47 | J13: 17.176 | K13: 7200.01 | L13: -544.95 | N13: 6655.06 | O13: 1663.77 | P13: 8318.83 | Q13: 762.13 | R13: =IF(G13="parking","",(K13+L13)/H13) -> 15.875999 | S13: =IF(ABS(ROUND(H13*J13,2)-K13)<=0.02,"OK","CHECK") -> OK | T13: =IF(ABS(ROUND(K13+L13+IF(M13="",0,M13),2)-N13)<=0.011,"OK","CHECK") -> OK | U13: =IF(ABS(ROUND(N13*0.25,2)-O13)<=0.07,"OK","CHECK") -> OK | V13: =IF(ABS(N13+O13-P13)<=0.011,"OK","CHECK") -> OK
A14: 26/651689595 | B14: 025 | C14: 2026-05-15 | D14: 16:49 | E14: PREEM | F14: ARLOV | G14: DIESEL | H14: 280.03 | I14: 21.47 | J14: 17.176 | K14: 4809.79 | L14: -364.04 | N14: 4445.75 | O14: 1111.44 | P14: 5557.19 | Q14: 509.12 | R14: =IF(G14="parking","",(K14+L14)/H14) -> 15.875978 | S14: =IF(ABS(ROUND(H14*J14,2)-K14)<=0.02,"OK","CHECK") -> OK | T14: =IF(ABS(ROUND(K14+L14+IF(M14="",0,M14),2)-N14)<=0.011,"OK","CHECK") -> OK | U14: =IF(ABS(ROUND(N14*0.25,2)-O14)<=0.07,"OK","CHECK") -> OK | V14: =IF(ABS(N14+O14-P14)<=0.011,"OK","CHECK") -> OK
A15: 26/651689595 | B15: 025 | C15: 2026-05-15 | D15: 17:01 | E15: PREEM | F15: ARLOV | G15: ADBLUE | H15: 11 | I15: 9.89 | J15: 7.9118 | K15: 87.03 | L15: -13.42 | N15: 73.61 | O15: 18.4 | P15: 92.01 | Q15: 8.43 | R15: =IF(G15="parking","",(K15+L15)/H15) -> 6.6918182 | S15: =IF(ABS(ROUND(H15*J15,2)-K15)<=0.02,"OK","CHECK") -> OK | T15: =IF(ABS(ROUND(K15+L15+IF(M15="",0,M15),2)-N15)<=0.011,"OK","CHECK") -> OK | U15: =IF(ABS(ROUND(N15*0.25,2)-O15)<=0.07,"OK","CHECK") -> OK | V15: =IF(ABS(N15+O15-P15)<=0.011,"OK","CHECK") -> OK
A16: 26/651689595 | B16: 028 | C16: 2026-05-01 | D16: 07:35 | E16: PREEM | F16: LANDSKRONA | G16: DIESEL | H16: 270 | I16: 21.22 | J16: 16.976 | K16: 4583.52 | L16: -351 | N16: 4232.52 | O16: 1058.13 | P16: 5290.65 | Q16: 490.54 | R16: =IF(G16="parking","",(K16+L16)/H16) -> 15.676 | S16: =IF(ABS(ROUND(H16*J16,2)-K16)<=0.02,"OK","CHECK") -> OK | T16: =IF(ABS(ROUND(K16+L16+IF(M16="",0,M16),2)-N16)<=0.011,"OK","CHECK") -> OK | U16: =IF(ABS(ROUND(N16*0.25,2)-O16)<=0.07,"OK","CHECK") -> OK | V16: =IF(ABS(N16+O16-P16)<=0.011,"OK","CHECK") -> OK
A17: 26/651689595 | B17: 028 | C17: 2026-05-01 | D17: 07:44 | E17: PREEM | F17: LANDSKRONA | G17: ADBLUE | H17: 32 | I17: 10.39 | J17: 8.3119 | K17: 265.98 | L17: -39.04 | N17: 226.94 | O17: 56.74 | P17: 283.68 | Q17: 26.3 | R17: =IF(G17="parking","",(K17+L17)/H17) -> 7.091875 | S17: =IF(ABS(ROUND(H17*J17,2)-K17)<=0.02,"OK","CHECK") -> OK | T17: =IF(ABS(ROUND(K17+L17+IF(M17="",0,M17),2)-N17)<=0.011,"OK","CHECK") -> OK | U17: =IF(ABS(ROUND(N17*0.25,2)-O17)<=0.07,"OK","CHECK") -> OK | V17: =IF(ABS(N17+O17-P17)<=0.011,"OK","CHECK") -> OK
A18: 26/651689595 | B18: 028 | C18: 2026-05-01 | D18: 07:48 | E18: PREEM | F18: LANDSKRONA | G18: DIESEL | H18: 340 | I18: 21.22 | J18: 16.976 | K18: 5771.84 | L18: -442 | N18: 5329.84 | O18: 1332.46 | P18: 6662.3 | Q18: 617.72 | R18: =IF(G18="parking","",(K18+L18)/H18) -> 15.676 | S18: =IF(ABS(ROUND(H18*J18,2)-K18)<=0.02,"OK","CHECK") -> OK | T18: =IF(ABS(ROUND(K18+L18+IF(M18="",0,M18),2)-N18)<=0.011,"OK","CHECK") -> OK | U18: =IF(ABS(ROUND(N18*0.25,2)-O18)<=0.07,"OK","CHECK") -> OK | V18: =IF(ABS(N18+O18-P18)<=0.011,"OK","CHECK") -> OK
A19: 26/651689595 | B19: 032 | C19: 2026-05-07 | D19: 22:35 | E19: PREEM | F19: GOTEBORG | G19: DIESEL | H19: 453.18 | I19: 22 | J19: 17.6 | K19: 7975.97 | L19: -589.13 | N19: 7386.84 | O19: 1846.71 | P19: 9233.55 | Q19: 856 | R19: =IF(G19="parking","",(K19+L19)/H19) -> 16.300013 | S19: =IF(ABS(ROUND(H19*J19,2)-K19)<=0.02,"OK","CHECK") -> OK | T19: =IF(ABS(ROUND(K19+L19+IF(M19="",0,M19),2)-N19)<=0.011,"OK","CHECK") -> OK | U19: =IF(ABS(ROUND(N19*0.25,2)-O19)<=0.07,"OK","CHECK") -> OK | V19: =IF(ABS(N19+O19-P19)<=0.011,"OK","CHECK") -> OK
A20: 26/651689595 | B20: 032 | C20: 2026-05-09 | D20: 09:07 | E20: CIRCLE K | F20: GOETEBORG | G20: parking | H20: 1 | I20: 990 | J20: 792 | K20: 792 | L20: 0 | M20: 44.55 | N20: 836.55 | O20: 209.14 | P20: 1045.69 | Q20: 96.94 | R20: =IF(G20="parking","",(K20+L20)/H20) | S20: =IF(ABS(ROUND(H20*J20,2)-K20)<=0.02,"OK","CHECK") -> OK | T20: =IF(ABS(ROUND(K20+L20+IF(M20="",0,M20),2)-N20)<=0.011,"OK","CHECK") -> OK | U20: =IF(ABS(ROUND(N20*0.25,2)-O20)<=0.07,"OK","CHECK") -> OK | V20: =IF(ABS(N20+O20-P20)<=0.011,"OK","CHECK") -> OK
A21: 26/651689595 | B21: 032 | C21: 2026-05-11 | D21: 06:44 | E21: PREEM | F21: GOTEBORG | G21: DIESEL | H21: 310 | I21: 21.47 | J21: 17.176 | K21: 5324.56 | L21: -403 | N21: 4921.56 | O21: 1230.39 | P21: 6151.95 | Q21: 567.93 | R21: =IF(G21="parking","",(K21+L21)/H21) -> 15.876 | S21: =IF(ABS(ROUND(H21*J21,2)-K21)<=0.02,"OK","CHECK") -> OK | T21: =IF(ABS(ROUND(K21+L21+IF(M21="",0,M21),2)-N21)<=0.011,"OK","CHECK") -> OK | U21: =IF(ABS(ROUND(N21*0.25,2)-O21)<=0.07,"OK","CHECK") -> OK | V21: =IF(ABS(N21+O21-P21)<=0.011,"OK","CHECK") -> OK
A22: 26/651689595 | B22: 032 | C22: 2026-05-12 | D22: 14:33 | E22: PREEM | F22: ARLOV | G22: DIESEL | H22: 282.45 | I22: 21.47 | J22: 17.176 | K22: 4851.36 | L22: -367.19 | N22: 4484.17 | O22: 1121.04 | P22: 5605.21 | Q22: 516.65 | R22: =IF(G22="parking","",(K22+L22)/H22) -> 15.875978 | S22: =IF(ABS(ROUND(H22*J22,2)-K22)<=0.02,"OK","CHECK") -> OK | T22: =IF(ABS(ROUND(K22+L22+IF(M22="",0,M22),2)-N22)<=0.011,"OK","CHECK") -> OK | U22: =IF(ABS(ROUND(N22*0.25,2)-O22)<=0.07,"OK","CHECK") -> OK | V22: =IF(ABS(N22+O22-P22)<=0.011,"OK","CHECK") -> OK
A23: 26/651689595 | B23: 032 | C23: 2026-05-12 | D23: 14:42 | E23: PREEM | F23: ARLOV | G23: DIESEL | H23: 150.01 | I23: 21.47 | J23: 17.176 | K23: 2576.57 | L23: -195.01 | N23: 2381.56 | O23: 595.39 | P23: 2976.95 | Q23: 274.39 | R23: =IF(G23="parking","",(K23+L23)/H23) -> 15.876008 | S23: =IF(ABS(ROUND(H23*J23,2)-K23)<=0.02,"OK","CHECK") -> OK | T23: =IF(ABS(ROUND(K23+L23+IF(M23="",0,M23),2)-N23)<=0.011,"OK","CHECK") -> OK | U23: =IF(ABS(ROUND(N23*0.25,2)-O23)<=0.07,"OK","CHECK") -> OK | V23: =IF(ABS(N23+O23-P23)<=0.011,"OK","CHECK") -> OK
A24: 26/651689595 | B24: 037 | C24: 2026-05-04 | D24: 15:25 | E24: PREEM | F24: VAXJO | G24: DIESEL | H24: 420.02 | I24: 22 | J24: 17.6 | K24: 7392.35 | L24: -546.03 | N24: 6846.32 | O24: 1711.58 | P24: 8557.9 | Q24: 792.45 | R24: =IF(G24="parking","",(K24+L24)/H24) -> 16.299986 | S24: =IF(ABS(ROUND(H24*J24,2)-K24)<=0.02,"OK","CHECK") -> OK | T24: =IF(ABS(ROUND(K24+L24+IF(M24="",0,M24),2)-N24)<=0.011,"OK","CHECK") -> OK | U24: =IF(ABS(ROUND(N24*0.25,2)-O24)<=0.07,"OK","CHECK") -> OK | V24: =IF(ABS(N24+O24-P24)<=0.011,"OK","CHECK") -> OK
A25: 26/651689595 | B25: 037 | C25: 2026-05-07 | D25: 23:11 | E25: PREEM | F25: GRANNA | G25: DIESEL | H25: 430 | I25: 22 | J25: 17.6 | K25: 7568 | L25: -559 | N25: 7009 | O25: 1752.25 | P25: 8761.25 | Q25: 812.22 | R25: =IF(G25="parking","",(K25+L25)/H25) -> 16.3 | S25: =IF(ABS(ROUND(H25*J25,2)-K25)<=0.02,"OK","CHECK") -> OK | T25: =IF(ABS(ROUND(K25+L25+IF(M25="",0,M25),2)-N25)<=0.011,"OK","CHECK") -> OK | U25: =IF(ABS(ROUND(N25*0.25,2)-O25)<=0.07,"OK","CHECK") -> OK | V25: =IF(ABS(N25+O25-P25)<=0.011,"OK","CHECK") -> OK
A26: 26/651689595 | B26: 037 | C26: 2026-05-07 | D26: 23:21 | E26: PREEM | F26: GRANNA | G26: ADBLUE | H26: 46.77 | I26: 10.39 | J26: 8.312 | K26: 388.75 | L26: -57.06 | N26: 331.69 | O26: 82.92 | P26: 414.61 | Q26: 38.43 | R26: =IF(G26="parking","",(K26+L26)/H26) -> 7.0919393 | S26: =IF(ABS(ROUND(H26*J26,2)-K26)<=0.02,"OK","CHECK") -> OK | T26: =IF(ABS(ROUND(K26+L26+IF(M26="",0,M26),2)-N26)<=0.011,"OK","CHECK") -> OK | U26: =IF(ABS(ROUND(N26*0.25,2)-O26)<=0.07,"OK","CHECK") -> OK | V26: =IF(ABS(N26+O26-P26)<=0.011,"OK","CHECK") -> OK
A27: 26/651689595 | B27: 037 | C27: 2026-05-11 | D27: 15:35 | E27: PREEM | F27: MARKARYD | G27: DIESEL | H27: 272.23 | I27: 21.47 | J27: 17.176 | K27: 4675.82 | L27: -353.9 | N27: 4321.92 | O27: 1080.48 | P27: 5402.4 | Q27: 498.74 | R27: =IF(G27="parking","",(K27+L27)/H27) -> 15.875987 | S27: =IF(ABS(ROUND(H27*J27,2)-K27)<=0.02,"OK","CHECK") -> OK | T27: =IF(ABS(ROUND(K27+L27+IF(M27="",0,M27),2)-N27)<=0.011,"OK","CHECK") -> OK | U27: =IF(ABS(ROUND(N27*0.25,2)-O27)<=0.07,"OK","CHECK") -> OK | V27: =IF(ABS(N27+O27-P27)<=0.011,"OK","CHECK") -> OK
A28: 26/651689595 | B28: 037 | C28: 2026-05-11 | D28: 15:42 | E28: PREEM | F28: MARKARYD | G28: DIESEL | H28: 250.5 | I28: 21.47 | J28: 17.176 | K28: 4302.59 | L28: -325.65 | N28: 3976.94 | O28: 994.24 | P28: 4971.18 | Q28: 458.93 | R28: =IF(G28="parking","",(K28+L28)/H28) -> 15.876008 | S28: =IF(ABS(ROUND(H28*J28,2)-K28)<=0.02,"OK","CHECK") -> OK | T28: =IF(ABS(ROUND(K28+L28+IF(M28="",0,M28),2)-N28)<=0.011,"OK","CHECK") -> OK | U28: =IF(ABS(ROUND(N28*0.25,2)-O28)<=0.07,"OK","CHECK") -> OK | V28: =IF(ABS(N28+O28-P28)<=0.011,"OK","CHECK") -> OK
A29: 26/651689595 | B29: 039 | C29: 2026-05-05 | D29: 19:43 | E29: OKQ8 | F29: TVAAKER | G29: parking | H29: 1 | I29: 140 | J29: 112 | K29: 112 | L29: 0 | M29: 6.3 | N29: 118.3 | O29: 29.58 | P29: 147.88 | Q29: 13.68 | R29: =IF(G29="parking","",(K29+L29)/H29) | S29: =IF(ABS(ROUND(H29*J29,2)-K29)<=0.02,"OK","CHECK") -> OK | T29: =IF(ABS(ROUND(K29+L29+IF(M29="",0,M29),2)-N29)<=0.011,"OK","CHECK") -> OK | U29: =IF(ABS(ROUND(N29*0.25,2)-O29)<=0.07,"OK","CHECK") -> OK | V29: =IF(ABS(N29+O29-P29)<=0.011,"OK","CHECK") -> OK
A30: 26/651689595 | B30: 039 | C30: 2026-05-06 | D30: 19:25 | E30: OKQ8 | F30: VASE | G30: parking | H30: 1 | I30: 130 | J30: 104 | K30: 104 | L30: 0 | M30: 5.85 | N30: 109.85 | O30: 27.46 | P30: 137.31 | Q30: 12.74 | R30: =IF(G30="parking","",(K30+L30)/H30) | S30: =IF(ABS(ROUND(H30*J30,2)-K30)<=0.02,"OK","CHECK") -> OK | T30: =IF(ABS(ROUND(K30+L30+IF(M30="",0,M30),2)-N30)<=0.011,"OK","CHECK") -> OK | U30: =IF(ABS(ROUND(N30*0.25,2)-O30)<=0.07,"OK","CHECK") -> OK | V30: =IF(ABS(N30+O30-P30)<=0.011,"OK","CHECK") -> OK
A31: 26/651689595 | B31: 046 | C31: 2026-05-06 | D31: 07:49 | E31: PREEM | F31: TRELLEBORG | G31: DIESEL | H31: 450 | I31: 22 | J31: 17.6 | K31: 7920 | L31: -585 | N31: 7335 | O31: 1833.75 | P31: 9168.75 | Q31: 850.97 | R31: =IF(G31="parking","",(K31+L31)/H31) -> 16.3 | S31: =IF(ABS(ROUND(H31*J31,2)-K31)<=0.02,"OK","CHECK") -> OK | T31: =IF(ABS(ROUND(K31+L31+IF(M31="",0,M31),2)-N31)<=0.011,"OK","CHECK") -> OK | U31: =IF(ABS(ROUND(N31*0.25,2)-O31)<=0.07,"OK","CHECK") -> OK | V31: =IF(ABS(N31+O31-P31)<=0.011,"OK","CHECK") -> OK
A32: 26/651689595 | B32: 046 | C32: 2026-05-06 | D32: 08:02 | E32: PREEM | F32: TRELLEBORG | G32: DIESEL | H32: 57.65 | I32: 22 | J32: 17.6 | K32: 1014.64 | L32: -74.95 | N32: 939.69 | O32: 234.92 | P32: 1174.61 | Q32: 109.01 | R32: =IF(G32="parking","",(K32+L32)/H32) -> 16.299913 | S32: =IF(ABS(ROUND(H32*J32,2)-K32)<=0.02,"OK","CHECK") -> OK | T32: =IF(ABS(ROUND(K32+L32+IF(M32="",0,M32),2)-N32)<=0.011,"OK","CHECK") -> OK | U32: =IF(ABS(ROUND(N32*0.25,2)-O32)<=0.07,"OK","CHECK") -> OK | V32: =IF(ABS(N32+O32-P32)<=0.011,"OK","CHECK") -> OK
A33: 26/651689595 | B33: 046 | C33: 2026-05-11 | D33: 11:31 | E33: PREEM | F33: TRELLEBORG | G33: DIESEL | H33: 461.11 | I33: 21.47 | J33: 17.176 | K33: 7920.02 | L33: -599.44 | N33: 7320.58 | O33: 1830.15 | P33: 9150.73 | Q33: 844.78 | R33: =IF(G33="parking","",(K33+L33)/H33) -> 15.875995 | S33: =IF(ABS(ROUND(H33*J33,2)-K33)<=0.02,"OK","CHECK") -> OK | T33: =IF(ABS(ROUND(K33+L33+IF(M33="",0,M33),2)-N33)<=0.011,"OK","CHECK") -> OK | U33: =IF(ABS(ROUND(N33*0.25,2)-O33)<=0.07,"OK","CHECK") -> OK | V33: =IF(ABS(N33+O33-P33)<=0.011,"OK","CHECK") -> OK
A34: 26/651689595 | B34: 046 | C34: 2026-05-11 | D34: 11:41 | E34: PREEM | F34: TRELLEBORG | G34: DIESEL | H34: 295.87 | I34: 21.47 | J34: 17.176 | K34: 5081.86 | L34: -384.63 | N34: 4697.23 | O34: 1174.31 | P34: 5871.54 | Q34: 542.05 | R34: =IF(G34="parking","",(K34+L34)/H34) -> 15.875993 | S34: =IF(ABS(ROUND(H34*J34,2)-K34)<=0.02,"OK","CHECK") -> OK | T34: =IF(ABS(ROUND(K34+L34+IF(M34="",0,M34),2)-N34)<=0.011,"OK","CHECK") -> OK | U34: =IF(ABS(ROUND(N34*0.25,2)-O34)<=0.07,"OK","CHECK") -> OK | V34: =IF(ABS(N34+O34-P34)<=0.011,"OK","CHECK") -> OK
A35: 26/651689595 | B35: 054 | C35: 2026-05-06 | D35: 20:36 | E35: PREEM | F35: HELSINGBORG | G35: ADBLUE | H35: 65.04 | I35: 10.3901 | J35: 8.3121 | K35: 540.62 | L35: -79.35 | N35: 461.27 | O35: 115.32 | P35: 576.59 | Q35: 53.51 | R35: =IF(G35="parking","",(K35+L35)/H35) -> 7.0920972 | S35: =IF(ABS(ROUND(H35*J35,2)-K35)<=0.02,"OK","CHECK") -> OK | T35: =IF(ABS(ROUND(K35+L35+IF(M35="",0,M35),2)-N35)<=0.011,"OK","CHECK") -> OK | U35: =IF(ABS(ROUND(N35*0.25,2)-O35)<=0.07,"OK","CHECK") -> OK | V35: =IF(ABS(N35+O35-P35)<=0.011,"OK","CHECK") -> OK
A36: 26/651689595 | B36: 054 | C36: 2026-05-12 | D36: 12:34 | E36: PREEM | F36: HELSINGBORG | G36: DIESEL | H36: 464.38 | I36: 21.47 | J36: 17.176 | K36: 7976.19 | L36: -603.69 | N36: 7372.5 | O36: 1843.13 | P36: 9215.63 | Q36: 849.43 | R36: =IF(G36="parking","",(K36+L36)/H36) -> 15.876007 | S36: =IF(ABS(ROUND(H36*J36,2)-K36)<=0.02,"OK","CHECK") -> OK | T36: =IF(ABS(ROUND(K36+L36+IF(M36="",0,M36),2)-N36)<=0.011,"OK","CHECK") -> OK | U36: =IF(ABS(ROUND(N36*0.25,2)-O36)<=0.07,"OK","CHECK") -> OK | V36: =IF(ABS(N36+O36-P36)<=0.011,"OK","CHECK") -> OK
A37: 26/651689595 | B37: 054 | C37: 2026-05-12 | D37: 12:41 | E37: PREEM | F37: HELSINGBORG | G37: DIESEL | H37: 342.57 | I37: 21.47 | J37: 17.176 | K37: 5883.98 | L37: -445.34 | N37: 5438.64 | O37: 1359.66 | P37: 6798.3 | Q37: 626.63 | R37: =IF(G37="parking","",(K37+L37)/H37) -> 15.875996 | S37: =IF(ABS(ROUND(H37*J37,2)-K37)<=0.02,"OK","CHECK") -> OK | T37: =IF(ABS(ROUND(K37+L37+IF(M37="",0,M37),2)-N37)<=0.011,"OK","CHECK") -> OK | U37: =IF(ABS(ROUND(N37*0.25,2)-O37)<=0.07,"OK","CHECK") -> OK | V37: =IF(ABS(N37+O37-P37)<=0.011,"OK","CHECK") -> OK
A38: 26/651689595 | B38: 054 | C38: 2026-05-12 | D38: 12:48 | E38: PREEM | F38: HELSINGBORG | G38: DIESEL | H38: 123.5 | I38: 21.47 | J38: 17.176 | K38: 2121.24 | L38: -160.55 | N38: 1960.69 | O38: 490.17 | P38: 2450.86 | Q38: 225.9 | R38: =IF(G38="parking","",(K38+L38)/H38) -> 15.876032 | S38: =IF(ABS(ROUND(H38*J38,2)-K38)<=0.02,"OK","CHECK") -> OK | T38: =IF(ABS(ROUND(K38+L38+IF(M38="",0,M38),2)-N38)<=0.011,"OK","CHECK") -> OK | U38: =IF(ABS(ROUND(N38*0.25,2)-O38)<=0.07,"OK","CHECK") -> OK | V38: =IF(ABS(N38+O38-P38)<=0.011,"OK","CHECK") -> OK
A39: 26/651689595 | B39: 055 | C39: 2026-05-05 | D39: 06:10 | E39: PREEM | F39: MARKARYD | G39: DIESEL | H39: 270.01 | I39: 22 | J39: 17.6 | K39: 4752.18 | L39: -351.01 | N39: 4401.17 | O39: 1100.29 | P39: 5501.46 | Q39: 509.1 | R39: =IF(G39="parking","",(K39+L39)/H39) -> 16.300026 | S39: =IF(ABS(ROUND(H39*J39,2)-K39)<=0.02,"OK","CHECK") -> OK | T39: =IF(ABS(ROUND(K39+L39+IF(M39="",0,M39),2)-N39)<=0.011,"OK","CHECK") -> OK | U39: =IF(ABS(ROUND(N39*0.25,2)-O39)<=0.07,"OK","CHECK") -> OK | V39: =IF(ABS(N39+O39-P39)<=0.011,"OK","CHECK") -> OK
A40: 26/651689595 | B40: 055 | C40: 2026-05-06 | D40: 14:50 | E40: PREEM | F40: ODESHOG | G40: DIESEL | H40: 195 | I40: 22 | J40: 17.6 | K40: 3432 | L40: -253.5 | N40: 3178.5 | O40: 794.63 | P40: 3973.13 | Q40: 368.76 | R40: =IF(G40="parking","",(K40+L40)/H40) -> 16.3 | S40: =IF(ABS(ROUND(H40*J40,2)-K40)<=0.02,"OK","CHECK") -> OK | T40: =IF(ABS(ROUND(K40+L40+IF(M40="",0,M40),2)-N40)<=0.011,"OK","CHECK") -> OK | U40: =IF(ABS(ROUND(N40*0.25,2)-O40)<=0.07,"OK","CHECK") -> OK | V40: =IF(ABS(N40+O40-P40)<=0.011,"OK","CHECK") -> OK
...

Sheet Card totals check
A1: Invoice | B1: Vehicle | C1: Stated: qty | D1: base | E1: disc | F1: fee | G1: net | H1: VAT | I1: gross | J1: EUR | K1: Calc net | L1: Calc gross | M1: Calc EUR | N1: Check
A2: 26/651689595 | B2: 009 | C2: 401.03 | D2: 7276.53 | E2: -520.04 | F2: 13.28 | G2: 6769.77 | H2: 1692.44 | I2: 8462.21 | J2: 783.1 | K2: =ROUND(SUMPRODUCT((Transactions!$A$2:$A$86=A2)*(Transactions!$B$2:$B$86=B2)*Transactions!$N$2:$N$86),2) -> 6769.77 | L2: =ROUND(SUMPRODUCT((Transactions!$A$2:$A$86=A2)*(Transactions!$B$2:$B$86=B2)*Transactions!$P$2:$P$86),2) -> 8462.21 | M2: =ROUND(SUMPRODUCT((Transactions!$A$2:$A$86=A2)*(Transactions!$B$2:$B$86=B2)*Transactions!$Q$2:$Q$86),2) -> 783.1 | N2: =IF(AND(ABS(K2-G2)<=0.02,ABS(L2-I2)<=0.02,ABS(M2-J2)<=0.02),"OK","CHECK") -> OK
A3: 26/651689595 | B3: 018 | C3: 1 | D3: 236 | E3: 0 | F3: 13.28 | G3: 249.28 | H3: 62.32 | I3: 311.6 | J3: 28.83 | K3: =ROUND(SUMPRODUCT((Transactions!$A$2:$A$86=A3)*(Transactions!$B$2:$B$86=B3)*Transactions!$N$2:$N$86),2) -> 249.28 | L3: =ROUND(SUMPRODUCT((Transactions!$A$2:$A$86=A3)*(Transactions!$B$2:$B$86=B3)*Transactions!$P$2:$P$86),2) -> 311.6 | M3: =ROUND(SUMPRODUCT((Transactions!$A$2:$A$86=A3)*(Transactions!$B$2:$B$86=B3)*Transactions!$Q$2:$Q$86),2) -> 28.83 | N3: =IF(AND(ABS(K3-G3)<=0.02,ABS(L3-I3)<=0.02,ABS(M3-J3)<=0.02),"OK","CHECK") -> OK
A4: 26/651689595 | B4: 022 | C4: 853.42 | D4: 14859.32 | E4: -1108.06 | F4: 0 | G4: 13751.26 | H4: 3437.82 | I4: 17189.08 | J4: 1593.38 | K4: =ROUND(SUMPRODUCT((Transactions!$A$2:$A$86=A4)*(Transactions!$B$2:$B$86=B4)*Transactions!$N$2:$N$86),2) -> 13751.26 | L4: =ROUND(SUMPRODUCT((Transactions!$A$2:$A$86=A4)*(Transactions!$B$2:$B$86=B4)*Transactions!$P$2:$P$86),2) -> 17189.08 | M4: =ROUND(SUMPRODUCT((Transactions!$A$2:$A$86=A4)*(Transactions!$B$2:$B$86=B4)*Transactions!$Q$2:$Q$86),2) -> 1593.38 | N4: =IF(AND(ABS(K4-G4)<=0.02,ABS(L4-I4)<=0.02,ABS(M4-J4)<=0.02),"OK","CHECK") -> OK
A5: 26/651689595 | B5: 025 | C5: 1236.81 | D5: 20850.28 | E5: -1601.27 | F5: 13.28 | G5: 19262.29 | H5: 4815.58 | I5: 24077.87 | J5: 2212.89 | K5: =ROUND(SUMPRODUCT((Transactions!$A$2:$A$86=A5)*(Transactions!$B$2:$B$86=B5)*Transactions!$N$2:$N$86),2) -> 19262.29 | L5: =ROUND(SUMPRODUCT((Transactions!$A$2:$A$86=A5)*(Transactions!$B$2:$B$86=B5)*Transactions!$P$2:$P$86),2) -> 24077.87 | M5: =ROUND(SUMPRODUCT((Transactions!$A$2:$A$86=A5)*(Transactions!$B$2:$B$86=B5)*Transactions!$Q$2:$Q$86),2) -> 2212.89 | N5: =IF(AND(ABS(K5-G5)<=0.02,ABS(L5-I5)<=0.02,ABS(M5-J5)<=0.02),"OK","CHECK") -> OK
A6: 26/651689595 | B6: 028 | C6: 642 | D6: 10621.34 | E6: -832.04 | F6: 0 | G6: 9789.3 | H6: 2447.33 | I6: 12236.63 | J6: 1134.56 | K6: =ROUND(SUMPRODUCT((Transactions!$A$2:$A$86=A6)*(Transactions!$B$2:$B$86=B6)*Transactions!$N$2:$N$86),2) -> 9789.3 | L6: =ROUND(SUMPRODUCT((Transactions!$A$2:$A$86=A6)*(Transactions!$B$2:$B$86=B6)*Transactions!$P$2:$P$86),2) -> 12236.63 | M6: =ROUND(SUMPRODUCT((Transactions!$A$2:$A$86=A6)*(Transactions!$B$2:$B$86=B6)*Transactions!$Q$2:$Q$86),2) -> 1134.56 | N6: =IF(AND(ABS(K6-G6)<=0.02,ABS(L6-I6)<=0.02,ABS(M6-J6)<=0.02),"OK","CHECK") -> OK
A7: 26/651689595 | B7: 032 | C7: 1196.64 | D7: 21520.46 | E7: -1554.33 | F7: 44.55 | G7: 20010.68 | H7: 5002.67 | I7: 25013.35 | J7: 2311.91 | K7: =ROUND(SUMPRODUCT((Transactions!$A$2:$A$86=A7)*(Transactions!$B$2:$B$86=B7)*Transactions!$N$2:$N$86),2) -> 20010.68 | L7: =ROUND(SUMPRODUCT((Transactions!$A$2:$A$86=A7)*(Transactions!$B$2:$B$86=B7)*Transactions!$P$2:$P$86),2) -> 25013.35 | M7: =ROUND(SUMPRODUCT((Transactions!$A$2:$A$86=A7)*(Transactions!$B$2:$B$86=B7)*Transactions!$Q$2:$Q$86),2) -> 2311.91 | N7: =IF(AND(ABS(K7-G7)<=0.02,ABS(L7-I7)<=0.02,ABS(M7-J7)<=0.02),"OK","CHECK") -> OK
A8: 26/651689595 | B8: 037 | C8: 1419.52 | D8: 24327.51 | E8: -1841.64 | F8: 0 | G8: 22485.87 | H8: 5621.47 | I8: 28107.34 | J8: 2600.77 | K8: =ROUND(SUMPRODUCT((Transactions!$A$2:$A$86=A8)*(Transactions!$B$2:$B$86=B8)*Transactions!$N$2:$N$86),2) -> 22485.87 | L8: =ROUND(SUMPRODUCT((Transactions!$A$2:$A$86=A8)*(Transactions!$B$2:$B$86=B8)*Transactions!$P$2:$P$86),2) -> 28107.34 | M8: =ROUND(SUMPRODUCT((Transactions!$A$2:$A$86=A8)*(Transactions!$B$2:$B$86=B8)*Transactions!$Q$2:$Q$86),2) -> 2600.77 | N8: =IF(AND(ABS(K8-G8)<=0.02,ABS(L8-I8)<=0.02,ABS(M8-J8)<=0.02),"OK","CHECK") -> OK
A9: 26/651689595 | B9: 039 | C9: 2 | D9: 216 | E9: 0 | F9: 12.15 | G9: 228.15 | H9: 57.04 | I9: 285.19 | J9: 26.42 | K9: =ROUND(SUMPRODUCT((Transactions!$A$2:$A$86=A9)*(Transactions!$B$2:$B$86=B9)*Transactions!$N$2:$N$86),2) -> 228.15 | L9: =ROUND(SUMPRODUCT((Transactions!$A$2:$A$86=A9)*(Transactions!$B$2:$B$86=B9)*Transactions!$P$2:$P$86),2) -> 285.19 | M9: =ROUND(SUMPRODUCT((Transactions!$A$2:$A$86=A9)*(Transactions!$B$2:$B$86=B9)*Transactions!$Q$2:$Q$86),2) -> 26.42 | N9: =IF(AND(ABS(K9-G9)<=0.02,ABS(L9-I9)<=0.02,ABS(M9-J9)<=0.02),"OK","CHECK") -> OK
A10: 26/651689595 | B10: 046 | C10: 1264.63 | D10: 21936.52 | E10: -1644.02 | F10: 0 | G10: 20292.5 | H10: 5073.13 | I10: 25365.63 | J10: 2346.81 | K10: =ROUND(SUMPRODUCT((Transactions!$A$2:$A$86=A10)*(Transactions!$B$2:$B$86=B10)*Transactions!$N$2:$N$86),2) -> 20292.5 | L10: =ROUND(SUMPRODUCT((Transactions!$A$2:$A$86=A10)*(Transactions!$B$2:$B$86=B10)*Transactions!$P$2:$P$86),2) -> 25365.63 | M10: =ROUND(SUMPRODUCT((Transactions!$A$2:$A$86=A10)*(Transactions!$B$2:$B$86=B10)*Transactions!$Q$2:$Q$86),2) -> 2346.81 | N10: =IF(AND(ABS(K10-G10)<=0.02,ABS(L10-I10)<=0.02,ABS(M10-J10)<=0.02),"OK","CHECK") -> OK
A11: 26/651689595 | B11: 054 | C11: 995.49 | D11: 16522.03 | E11: -1288.93 | F11: 0 | G11: 15233.1 | H11: 3808.28 | I11: 19041.38 | J11: 1755.47 | K11: =ROUND(SUMPRODUCT((Transactions!$A$2:$A$86=A11)*(Transactions!$B$2:$B$86=B11)*Transactions!$N$2:$N$86),2) -> 15233.1 | L11: =ROUND(SUMPRODUCT((Transactions!$A$2:$A$86=A11)*(Transactions!$B$2:$B$86=B11)*Transactions!$P$2:$P$86),2) -> 19041.38 | M11: =ROUND(SUMPRODUCT((Transactions!$A$2:$A$86=A11)*(Transactions!$B$2:$B$86=B11)*Transactions!$Q$2:$Q$86),2) -> 1755.47 | N11: =IF(AND(ABS(K11-G11)<=0.02,ABS(L11-I11)<=0.02,ABS(M11-J11)<=0.02),"OK","CHECK") -> OK
A12: 26/651689595 | B12: 055 | C12: 1168.4 | D12: 19844.55 | E12: -1514.56 | F12: 0 | G12: 18329.99 | H12: 4582.46 | I12: 22912.45 | J12: 2116.67 | K12: =ROUND(SUMPRODUCT((Transactions!$A$2:$A$86=A12)*(Transactions!$B$2:$B$86=B12)*Transactions!$N$2:$N$86),2) -> 18329.99 | L12: =ROUND(SUMPRODUCT((Transactions!$A$2:$A$86=A12)*(Transactions!$B$2:$B$86=B12)*Transactions!$P$2:$P$86),2) -> 22912.45 | M12: =ROUND(SUMPRODUCT((Transactions!$A$2:$A$86=A12)*(Transactions!$B$2:$B$86=B12)*Transactions!$Q$2:$Q$86),2) -> 2116.67 | N12: =IF(AND(ABS(K12-G12)<=0.02,ABS(L12-I12)<=0.02,ABS(M12-J12)<=0.02),"OK","CHECK") -> OK
A13: 26/651689595 | B13: 056 | C13: 1586.63 | D13: 26926.25 | E13: -2056.83 | F13: 0 | G13: 24869.42 | H13: 6217.36 | I13: 31086.78 | J13: 2868.45 | K13: =ROUND(SUMPRODUCT((Transactions!$A$2:$A$86=A13)*(Transactions!$B$2:$B$86=B13)*Transactions!$N$2:$N$86),2) -> 24869.42 | L13: =ROUND(SUMPRODUCT((Transactions!$A$2:$A$86=A13)*(Transactions!$B$2:$B$86=B13)*Transactions!$P$2:$P$86),2) -> 31086.78 | M13: =ROUND(SUMPRODUCT((Transactions!$A$2:$A$86=A13)*(Transactions!$B$2:$B$86=B13)*Transactions!$Q$2:$Q$86),2) -> 2868.45 | N13: =IF(AND(ABS(K13-G13)<=0.02,ABS(L13-I13)<=0.02,ABS(M13-J13)<=0.02),"OK","CHECK") -> OK
... A22: 26/652169828 | B22: 056 | C22: 1165.48 | D22: 19458.53 | E22: -1510.44 | F22: 0 | G22: 17948.09 | H22: 4487.03 | I22: 22435.12 | J22: 2087.38 | K22: =ROUND(SUMPRODUCT((Transactions!$A$2:$A$86=A22)*(Transactions!$B$2:$B$86=B22)*Transactions!$N$2:$N$86),2) -> 17948.09 | L22: =ROUND(SUMPRODUCT((Transactions!$A$2:$A$86=A22)*(Transactions!$B$2:$B$86=B22)*Transactions!$P$2:$P$86),2) -> 22435.12 | M22: =ROUND(SUMPRODUCT((Transactions!$A$2:$A$86=A22)*(Transactions!$B$2:$B$86=B22)*Transactions!$Q$2:$Q$86),2) -> 2087.38 | N22: =IF(AND(ABS(K22-G22)<=0.02,ABS(L22-I22)<=0.02,ABS(M22-J22)<=0.02),"OK","CHECK") -> OK

Sheet Invoice totals check
A1: Check item | B1: Invoice states | C1: Calculated | D1: Diff | E1: Check
A2: 26/651689595 DIESEL litres | B2: 10407.49 | C2: =ROUND(SUMPRODUCT((Transactions!$A$2:$A$86="26/651689595")*(Transactions!$G$2:$G$86="DIESEL")*Transactions!$H$2:$H$86),2) -> 10407.49 | D2: =C2-B2 -> 0 | E2: =IF(ABS(D2)<=0.02,"OK","CHECK") -> OK
A3: 26/651689595 DIESEL net SEK | B3: 166997.74 | C3: =ROUND(SUMPRODUCT((Transactions!$A$2:$A$86="26/651689595")*(Transactions!$G$2:$G$86="DIESEL")*Transactions!$N$2:$N$86),2) -> 166997.74 | D3: =C3-B3 -> 0 | E3: =IF(ABS(D3)<=0.02,"OK","CHECK") -> OK
A4: 26/651689595 ADBLUE litres | B4: 354.08 | C4: =ROUND(SUMPRODUCT((Transactions!$A$2:$A$86="26/651689595")*(Transactions!$G$2:$G$86="ADBLUE")*Transactions!$H$2:$H$86),2) -> 354.08 | D4: =C4-B4 -> 0 | E4: =IF(ABS(D4)<=0.02,"OK","CHECK") -> OK
A5: 26/651689595 ADBLUE net SEK | B5: 2461.33 | C5: =ROUND(SUMPRODUCT((Transactions!$A$2:$A$86="26/651689595")*(Transactions!$G$2:$G$86="ADBLUE")*Transactions!$N$2:$N$86),2) -> 2461.33 | D5: =C5-B5 -> 0 | E5: =IF(ABS(D5)<=0.02,"OK","CHECK") -> OK
A6: 26/651689595 parking net SEK | B6: 1812.54 | C6: =ROUND(SUMPRODUCT((Transactions!$A$2:$A$86="26/651689595")*(Transactions!$G$2:$G$86="parking")*Transactions!$N$2:$N$86),2) -> 1812.54 | D6: =C6-B6 -> 0 | E6: =IF(ABS(D6)<=0.02,"OK","CHECK") -> OK
A7: 26/651689595 TOTAL net SEK | B7: 171271.61 | C7: =ROUND(SUMIF(Transactions!$A$2:$A$86,"26/651689595",Transactions!$N$2:$N$86),2) -> 171271.61 | D7: =C7-B7 -> 0 | E7: =IF(ABS(D7)<=0.02,"OK","CHECK") -> OK
A8: 26/651689595 TOTAL VAT SEK | B8: 42817.9 | C8: =ROUND(SUMIF(Transactions!$A$2:$A$86,"26/651689595",Transactions!$O$2:$O$86),2) -> 42817.9 | D8: =C8-B8 -> 0 | E8: =IF(ABS(D8)<=0.02,"OK","CHECK") -> OK
A9: 26/651689595 TOTAL gross SEK | B9: 214089.51 | C9: =ROUND(SUMIF(Transactions!$A$2:$A$86,"26/651689595",Transactions!$P$2:$P$86),2) -> 214089.51 | D9: =C9-B9 -> 0 | E9: =IF(ABS(D9)<=0.02,"OK","CHECK") -> OK
A10: 26/651689595 TOTAL payable EUR | B10: 19779.26 | C10: =ROUND(SUMIF(Transactions!$A$2:$A$86,"26/651689595",Transactions!$Q$2:$Q$86),2) -> 19779.26 | D10: =C10-B10 -> 0 | E10: =IF(ABS(D10)<=0.02,"OK","CHECK") -> OK
A11: 26/652169828 DIESEL litres | B11: 6924.39 | C11: =ROUND(SUMPRODUCT((Transactions!$A$2:$A$86="26/652169828")*(Transactions!$G$2:$G$86="DIESEL")*Transactions!$H$2:$H$86),2) -> 6924.39 | D11: =C11-B11 -> 0 | E11: =IF(ABS(D11)<=0.02,"OK","CHECK") -> OK
A12: 26/652169828 DIESEL net SEK | B12: 109108.85 | C12: =ROUND(SUMPRODUCT((Transactions!$A$2:$A$86="26/652169828")*(Transactions!$G$2:$G$86="DIESEL")*Transactions!$N$2:$N$86),2) -> 109108.85 | D12: =C12-B12 -> 0 | E12: =IF(ABS(D12)<=0.02,"OK","CHECK") -> OK
A13: 26/652169828 ADBLUE litres | B13: 400.23 | C13: =ROUND(SUMPRODUCT((Transactions!$A$2:$A$86="26/652169828")*(Transactions!$G$2:$G$86="ADBLUE")*Transactions!$H$2:$H$86),2) -> 400.23 | D13: =C13-B13 -> 0 | E13: =IF(ABS(D13)<=0.02,"OK","CHECK") -> OK
A14: 26/652169828 ADBLUE net SEK | B14: 2678.35 | C14: =ROUND(SUMPRODUCT((Transactions!$A$2:$A$86="26/652169828")*(Transactions!$G$2:$G$86="ADBLUE")*Transactions!$N$2:$N$86),2) -> 2678.35 | D14: =C14-B14 -> 0 | E14: =IF(ABS(D14)<=0.02,"OK","CHECK") -> OK
A15: 26/652169828 HVO 100 litres | B15: 251 | C15: =ROUND(SUMPRODUCT((Transactions!$A$2:$A$86="26/652169828")*(Transactions!$G$2:$G$86="HVO 100")*Transactions!$H$2:$H$86),2) -> 251 | D15: =C15-B15 -> 0 | E15: =IF(ABS(D15)<=0.02,"OK","CHECK") -> OK
A16: 26/652169828 HVO 100 net SEK | B16: 5732.34 | C16: =ROUND(SUMPRODUCT((Transactions!$A$2:$A$86="26/652169828")*(Transactions!$G$2:$G$86="HVO 100")*Transactions!$N$2:$N$86),2) -> 5732.34 | D16: =C16-B16 -> 0 | E16: =IF(ABS(D16)<=0.02,"OK","CHECK") -> OK
A17: 26/652169828 parking net SEK | B17: 1144.99 | C17: =ROUND(SUMPRODUCT((Transactions!$A$2:$A$86="26/652169828")*(Transactions!$G$2:$G$86="parking")*Transactions!$N$2:$N$86),2) -> 1144.99 | D17: =C17-B17 -> 0 | E17: =IF(ABS(D17)<=0.02,"OK","CHECK") -> OK
A18: 26/652169828 TOTAL net SEK | B18: 118664.53 | C18: =ROUND(SUMIF(Transactions!$A$2:$A$86,"26/652169828",Transactions!$N$2:$N$86),2) -> 118664.53 | D18: =C18-B18 -> 0 | E18: =IF(ABS(D18)<=0.02,"OK","CHECK") -> OK
A19: 26/652169828 TOTAL VAT SEK | B19: 29666.13 | C19: =ROUND(SUMIF(Transactions!$A$2:$A$86,"26/652169828",Transactions!$O$2:$O$86),2) -> 29666.13 | D19: =C19-B19 -> 0 | E19: =IF(ABS(D19)<=0.02,"OK","CHECK") -> OK
A20: 26/652169828 TOTAL gross SEK | B20: 148330.66 | C20: =ROUND(SUMIF(Transactions!$A$2:$A$86,"26/652169828",Transactions!$P$2:$P$86),2) -> 148330.66 | D20: =C20-B20 -> 0 | E20: =IF(ABS(D20)<=0.02,"OK","CHECK") -> OK
A21: 26/652169828 TOTAL payable EUR | B21: 13757.93 | C21: =ROUND(SUMIF(Transactions!$A$2:$A$86,"26/652169828",Transactions!$Q$2:$Q$86),2) -> 13757.93 | D21: =C21-B21 -> 0 | E21: =IF(ABS(D21)<=0.02,"OK","CHECK") -> OK
A22: BOTH invoices gross SEK | B22: 362420.17 | C22: =ROUND(SUM(Transactions!$P$2:$P$86),2) -> 362420.17 | D22: =C22-B22 -> 0 | E22: =IF(ABS(D22)<=0.02,"OK","CHECK") -> OK
A23: BOTH invoices payable EUR | B23: 33537.19 | C23: =ROUND(SUM(Transactions!$Q$2:$Q$86),2) -> 33537.19 | D23: =C23-B23 -> 0 | E23: =IF(ABS(D23)<=0.02,"OK","CHECK") -> OK
A24: BOTH Swedish VAT SEK (reclaimable) | B24: 72484.03 | C24: =ROUND(SUM(Transactions!$O$2:$O$86),2) -> 72484.03 | D24: =C24-B24 -> 0 | E24: =IF(ABS(D24)<=0.02,"OK","CHECK") -> OK
