Workbook

Sheet Transactions
A1: Card | B1: Date | C1: Time | D1: Receipt | E1: Plate | F1: Product | G1: Location | H1: Volume L | I1: Location price EUR/L | J1: Discount EUR/L | K1: Net price EUR/L (doc) | L1: Net amount EUR (doc) | M1: Eff. price used | N1: Check1: price math | O1: Calc amount | P1: Diff | Q1: Check2: amount
A2: 108019237 | B2: 27-05-26 | C2: 11:42 | D2: 110795 | E2: NCK 218 | F2: Diesel | G2: Romac Houdeng | H2: 456 | I2: 1.5944 | L2: 727.05 | M2: =IF(K2<>"",K2,I2) -> 1.5944 | N2: =IF(K2="","n/a (no discount)",IF(ABS(I2-J2-K2)<=0.0001,"OK","CHECK")) -> n/a (no discount) | O2: =ROUND(M2*H2,2) -> 727.05 | P2: =O2-L2 -> 0 | Q2: =IF(ABS(P2)<=0.011,"OK","CHECK") -> OK
A3: 108019237 | B3: 27-05-26 | C3: 11:50 | D3: 110817 | E3: NCK 218 | F3: Diesel | G3: Romac Houdeng | H3: 51 | I3: 1.5944 | L3: 81.32 | M3: =IF(K3<>"",K3,I3) -> 1.5944 | N3: =IF(K3="","n/a (no discount)",IF(ABS(I3-J3-K3)<=0.0001,"OK","CHECK")) -> n/a (no discount) | O3: =ROUND(M3*H3,2) -> 81.31 | P3: =O3-L3 -> -0.01 | Q3: =IF(ABS(P3)<=0.011,"OK","CHECK") -> OK
A4: 108019237 | B4: 27-05-26 | C4: 11:54 | D4: 110829 | E4: NCK 218 | F4: Diesel | G4: Romac Houdeng | H4: 24 | I4: 1.5944 | L4: 38.27 | M4: =IF(K4<>"",K4,I4) -> 1.5944 | N4: =IF(K4="","n/a (no discount)",IF(ABS(I4-J4-K4)<=0.0001,"OK","CHECK")) -> n/a (no discount) | O4: =ROUND(M4*H4,2) -> 38.27 | P4: =O4-L4 -> 0 | Q4: =IF(ABS(P4)<=0.011,"OK","CHECK") -> OK
A5: 108019237 | B5: 29-05-26 | C5: 15:10 | D5: 117360 | E5: NCK 218 | F5: Diesel | G5: Tfc Dcb Energy Hub Meer | H5: 271 | I5: 1.6843 | J5: 0.205 | K5: 1.4793 | L5: 400.9 | M5: =IF(K5<>"",K5,I5) -> 1.4793 | N5: =IF(K5="","n/a (no discount)",IF(ABS(I5-J5-K5)<=0.0001,"OK","CHECK")) -> OK | O5: =ROUND(M5*H5,2) -> 400.89 | P5: =O5-L5 -> -0.01 | Q5: =IF(ABS(P5)<=0.011,"OK","CHECK") -> OK
A6: 108019237 | B6: 29-05-26 | C6: 15:19 | D6: 117410 | E6: NCK 218 | F6: Diesel | G6: Tfc Dcb Energy Hub Meer | H6: 26 | I6: 1.6843 | J6: 0.205 | K6: 1.4793 | L6: 38.47 | M6: =IF(K6<>"",K6,I6) -> 1.4793 | N6: =IF(K6="","n/a (no discount)",IF(ABS(I6-J6-K6)<=0.0001,"OK","CHECK")) -> OK | O6: =ROUND(M6*H6,2) -> 38.46 | P6: =O6-L6 -> -0.01 | Q6: =IF(ABS(P6)<=0.011,"OK","CHECK") -> OK
A7: 108019237 | B7: 29-05-26 | C7: 15:21 | D7: 117425 | E7: NCK 218 | F7: Diesel | G7: Tfc Dcb Energy Hub Meer | H7: 137.01 | I7: 1.6843 | J7: 0.205 | K7: 1.4793 | L7: 202.68 | M7: =IF(K7<>"",K7,I7) -> 1.4793 | N7: =IF(K7="","n/a (no discount)",IF(ABS(I7-J7-K7)<=0.0001,"OK","CHECK")) -> OK | O7: =ROUND(M7*H7,2) -> 202.68 | P7: =O7-L7 -> 0 | Q7: =IF(ABS(P7)<=0.011,"OK","CHECK") -> OK
A8: 108019237 | B8: 27-05-26 | C8: 11:47 | D8: 110809 | E8: NCK 218 | F8: AdBlue | G8: Romac Houdeng | H8: 30 | I8: 0.675 | L8: 20.25 | M8: =IF(K8<>"",K8,I8) -> 0.675 | N8: =IF(K8="","n/a (no discount)",IF(ABS(I8-J8-K8)<=0.0001,"OK","CHECK")) -> n/a (no discount) | O8: =ROUND(M8*H8,2) -> 20.25 | P8: =O8-L8 -> 0 | Q8: =IF(ABS(P8)<=0.011,"OK","CHECK") -> OK
A9: 108019237 | B9: 29-05-26 | C9: 15:15 | D9: 117389 | E9: NCK 218 | F9: AdBlue | G9: Tfc Dcb Energy Hub Meer | H9: 48.11 | I9: 0.6 | J9: 0 | K9: 0.6 | L9: 28.87 | M9: =IF(K9<>"",K9,I9) -> 0.6 | N9: =IF(K9="","n/a (no discount)",IF(ABS(I9-J9-K9)<=0.0001,"OK","CHECK")) -> OK | O9: =ROUND(M9*H9,2) -> 28.87 | P9: =O9-L9 -> 0 | Q9: =IF(ABS(P9)<=0.011,"OK","CHECK") -> OK
A10: 145993502 | B10: 18-05-26 | C10: 13:38 | D10: 84860 | E10: MSZ552 | F10: Diesel | G10: Tfc Dcb Energy Hub Meer | H10: 445 | I10: 1.7488 | J10: 0.205 | K10: 1.5438 | L10: 687 | M10: =IF(K10<>"",K10,I10) -> 1.5438 | N10: =IF(K10="","n/a (no discount)",IF(ABS(I10-J10-K10)<=0.0001,"OK","CHECK")) -> OK | O10: =ROUND(M10*H10,2) -> 686.99 | P10: =O10-L10 -> -0.01 | Q10: =IF(ABS(P10)<=0.011,"OK","CHECK") -> OK
A11: 145993502 | B11: 18-05-26 | C11: 13:51 | D11: 84902 | E11: MSZ552 | F11: Diesel | G11: Tfc Dcb Energy Hub Meer | H11: 55 | I11: 1.7488 | J11: 0.205 | K11: 1.5438 | L11: 84.91 | M11: =IF(K11<>"",K11,I11) -> 1.5438 | N11: =IF(K11="","n/a (no discount)",IF(ABS(I11-J11-K11)<=0.0001,"OK","CHECK")) -> OK | O11: =ROUND(M11*H11,2) -> 84.91 | P11: =O11-L11 -> 0 | Q11: =IF(ABS(P11)<=0.011,"OK","CHECK") -> OK
A12: 145993502 | B12: 18-05-26 | C12: 13:46 | D12: 84891 | E12: MSZ552 | F12: AdBlue | G12: Tfc Dcb Energy Hub Meer | H12: 44 | I12: 0.6 | J12: 0 | K12: 0.6 | L12: 26.4 | M12: =IF(K12<>"",K12,I12) -> 0.6 | N12: =IF(K12="","n/a (no discount)",IF(ABS(I12-J12-K12)<=0.0001,"OK","CHECK")) -> OK | O12: =ROUND(M12*H12,2) -> 26.4 | P12: =O12-L12 -> 0 | Q12: =IF(ABS(P12)<=0.011,"OK","CHECK") -> OK
A13: 168404872 | B13: 21-05-26 | C13: 13:25 | D13: 95615 | E13: AII 954 | F13: Diesel | G13: Tfc Dcb Energy Hub Meer 2 | H13: 495 | I13: 1.8116 | J13: 0.205 | K13: 1.6066 | L13: 795.27 | M13: =IF(K13<>"",K13,I13) -> 1.6066 | N13: =IF(K13="","n/a (no discount)",IF(ABS(I13-J13-K13)<=0.0001,"OK","CHECK")) -> OK | O13: =ROUND(M13*H13,2) -> 795.27 | P13: =O13-L13 -> 0 | Q13: =IF(ABS(P13)<=0.011,"OK","CHECK") -> OK
A14: 168404872 | B14: 21-05-26 | C14: 13:32 | D14: 95632 | E14: AII 954 | F14: Diesel | G14: Tfc Dcb Energy Hub Meer 2 | H14: 260.02 | I14: 1.8116 | J14: 0.205 | K14: 1.6066 | L14: 417.75 | M14: =IF(K14<>"",K14,I14) -> 1.6066 | N14: =IF(K14="","n/a (no discount)",IF(ABS(I14-J14-K14)<=0.0001,"OK","CHECK")) -> OK | O14: =ROUND(M14*H14,2) -> 417.75 | P14: =O14-L14 -> 0 | Q14: =IF(ABS(P14)<=0.011,"OK","CHECK") -> OK
A15: 168404872 | B15: 21-05-26 | C15: 13:39 | D15: 95650 | E15: AII 954 | F15: Diesel | G15: Tfc Dcb Energy Hub Meer 2 | H15: 129 | I15: 1.8116 | J15: 0.205 | K15: 1.6066 | L15: 207.26 | M15: =IF(K15<>"",K15,I15) -> 1.6066 | N15: =IF(K15="","n/a (no discount)",IF(ABS(I15-J15-K15)<=0.0001,"OK","CHECK")) -> OK | O15: =ROUND(M15*H15,2) -> 207.25 | P15: =O15-L15 -> -0.01 | Q15: =IF(ABS(P15)<=0.011,"OK","CHECK") -> OK
A16: 168404872 | B16: 21-05-26 | C16: 13:42 | D16: 95664 | E16: AII 954 | F16: AdBlue | G16: Tfc Dcb Energy Hub Meer 2 | H16: 81.02 | I16: 0.6 | J16: 0 | K16: 0.6 | L16: 48.62 | M16: =IF(K16<>"",K16,I16) -> 0.6 | N16: =IF(K16="","n/a (no discount)",IF(ABS(I16-J16-K16)<=0.0001,"OK","CHECK")) -> OK | O16: =ROUND(M16*H16,2) -> 48.61 | P16: =O16-L16 -> -0.01 | Q16: =IF(ABS(P16)<=0.011,"OK","CHECK") -> OK
A17: 280623763 | B17: 18-05-26 | C17: 08:25 | D17: 84064 | E17: NCK 230 | F17: Diesel | G17: Tfc Dcb Energy Hub Meer | H17: 602.43 | I17: 1.7488 | J17: 0.205 | K17: 1.5438 | L17: 930.04 | M17: =IF(K17<>"",K17,I17) -> 1.5438 | N17: =IF(K17="","n/a (no discount)",IF(ABS(I17-J17-K17)<=0.0001,"OK","CHECK")) -> OK | O17: =ROUND(M17*H17,2) -> 930.03 | P17: =O17-L17 -> -0.01 | Q17: =IF(ABS(P17)<=0.011,"OK","CHECK") -> OK
A18: 280623763 | B18: 18-05-26 | C18: 08:41 | D18: 84092 | E18: NCK 230 | F18: Diesel | G18: Tfc Dcb Energy Hub Meer | H18: 303.85 | I18: 1.7488 | J18: 0.205 | K18: 1.5438 | L18: 469.09 | M18: =IF(K18<>"",K18,I18) -> 1.5438 | N18: =IF(K18="","n/a (no discount)",IF(ABS(I18-J18-K18)<=0.0001,"OK","CHECK")) -> OK | O18: =ROUND(M18*H18,2) -> 469.08 | P18: =O18-L18 -> -0.01 | Q18: =IF(ABS(P18)<=0.011,"OK","CHECK") -> OK
A19: 280623763 | B19: 18-05-26 | C19: 08:45 | D19: 84104 | E19: NCK 230 | F19: Diesel | G19: Tfc Dcb Energy Hub Meer | H19: 16.77 | I19: 1.7488 | J19: 0.205 | K19: 1.5438 | L19: 25.89 | M19: =IF(K19<>"",K19,I19) -> 1.5438 | N19: =IF(K19="","n/a (no discount)",IF(ABS(I19-J19-K19)<=0.0001,"OK","CHECK")) -> OK | O19: =ROUND(M19*H19,2) -> 25.89 | P19: =O19-L19 -> 0 | Q19: =IF(ABS(P19)<=0.011,"OK","CHECK") -> OK
A20: 280623763 | B20: 22-05-26 | C20: 14:19 | D20: 98837 | E20: NCK 230 | F20: Diesel | G20: Tfc Dcb Energy Hub Meer 2 | H20: 301.16 | I20: 1.7694 | J20: 0.205 | K20: 1.5644 | L20: 471.14 | M20: =IF(K20<>"",K20,I20) -> 1.5644 | N20: =IF(K20="","n/a (no discount)",IF(ABS(I20-J20-K20)<=0.0001,"OK","CHECK")) -> OK | O20: =ROUND(M20*H20,2) -> 471.13 | P20: =O20-L20 -> -0.01 | Q20: =IF(ABS(P20)<=0.011,"OK","CHECK") -> OK
... A26: 332206574 | B26: 29-05-26 | C26: 14:28 | D26: 251689 | E26: MTZ159 | F26: Diesel | G26: Dcb Energy Hub Maasmechelen | H26: 154.53 | I26: 1.6843 | J26: 0.19 | K26: 1.4943 | L26: 230.92 | M26: =IF(K26<>"",K26,I26) -> 1.4943 | N26: =IF(K26="","n/a (no discount)",IF(ABS(I26-J26-K26)<=0.0001,"OK","CHECK")) -> OK | O26: =ROUND(M26*H26,2) -> 230.91 | P26: =O26-L26 -> -0.01 | Q26: =IF(ABS(P26)<=0.011,"OK","CHECK") -> OK
A27: 332206574 | B27: 29-05-26 | C27: 14:12 | D27: 251662 | E27: MTZ159 | F27: AdBlue | G27: Dcb Energy Hub Maasmechelen | H27: 58.93 | I27: 0.675 | L27: 39.78 | M27: =IF(K27<>"",K27,I27) -> 0.675 | N27: =IF(K27="","n/a (no discount)",IF(ABS(I27-J27-K27)<=0.0001,"OK","CHECK")) -> n/a (no discount) | O27: =ROUND(M27*H27,2) -> 39.78 | P27: =O27-L27 -> 0 | Q27: =IF(ABS(P27)<=0.011,"OK","CHECK") -> OK
A28: 368425169 | B28: 23-05-26 | C28: 03:55 | D28: 100414 | E28: MSZ543 | F28: Diesel | G28: Tfc Dcb Energy Hub Meer 2 | H28: 555 | I28: 1.7694 | J28: 0.205 | K28: 1.5644 | L28: 868.25 | M28: =IF(K28<>"",K28,I28) -> 1.5644 | N28: =IF(K28="","n/a (no discount)",IF(ABS(I28-J28-K28)<=0.0001,"OK","CHECK")) -> OK | O28: =ROUND(M28*H28,2) -> 868.24 | P28: =O28-L28 -> -0.01 | Q28: =IF(ABS(P28)<=0.011,"OK","CHECK") -> OK
A29: 368425169 | B29: 23-05-26 | C29: 04:03 | D29: 100424 | E29: MSZ543 | F29: Diesel | G29: Tfc Dcb Energy Hub Meer 2 | H29: 300 | I29: 1.7694 | J29: 0.205 | K29: 1.5644 | L29: 469.32 | M29: =IF(K29<>"",K29,I29) -> 1.5644 | N29: =IF(K29="","n/a (no discount)",IF(ABS(I29-J29-K29)<=0.0001,"OK","CHECK")) -> OK | O29: =ROUND(M29*H29,2) -> 469.32 | P29: =O29-L29 -> 0 | Q29: =IF(ABS(P29)<=0.011,"OK","CHECK") -> OK
A30: 368425169 | B30: 23-05-26 | C30: 04:13 | D30: 100438 | E30: MSZ543 | F30: Diesel | G30: Tfc Dcb Energy Hub Meer 2 | H30: 160 | I30: 1.7694 | J30: 0.205 | K30: 1.5644 | L30: 250.31 | M30: =IF(K30<>"",K30,I30) -> 1.5644 | N30: =IF(K30="","n/a (no discount)",IF(ABS(I30-J30-K30)<=0.0001,"OK","CHECK")) -> OK | O30: =ROUND(M30*H30,2) -> 250.3 | P30: =O30-L30 -> -0.01 | Q30: =IF(ABS(P30)<=0.011,"OK","CHECK") -> OK
A31: 368425169 | B31: 23-05-26 | C31: 04:08 | D31: 100431 | E31: MSZ543 | F31: AdBlue | G31: Tfc Dcb Energy Hub Meer 2 | H31: 57 | I31: 0.6 | J31: 0 | K31: 0.6 | L31: 34.2 | M31: =IF(K31<>"",K31,I31) -> 0.6 | N31: =IF(K31="","n/a (no discount)",IF(ABS(I31-J31-K31)<=0.0001,"OK","CHECK")) -> OK | O31: =ROUND(M31*H31,2) -> 34.2 | P31: =O31-L31 -> 0 | Q31: =IF(ABS(P31)<=0.011,"OK","CHECK") -> OK
A32: 390924019 | B32: 26-05-26 | C32: 12:50 | D32: 107916 | E32: NNJ 874 | F32: Diesel | G32: Tfc Dcb Energy Hub Meer 2 | H32: 580 | I32: 1.7694 | J32: 0.205 | K32: 1.5644 | L32: 907.36 | M32: =IF(K32<>"",K32,I32) -> 1.5644 | N32: =IF(K32="","n/a (no discount)",IF(ABS(I32-J32-K32)<=0.0001,"OK","CHECK")) -> OK | O32: =ROUND(M32*H32,2) -> 907.35 | P32: =O32-L32 -> -0.01 | Q32: =IF(ABS(P32)<=0.011,"OK","CHECK") -> OK
A33: 390924019 | B33: 26-05-26 | C33: 12:58 | D33: 107938 | E33: NNJ 874 | F33: Diesel | G33: Tfc Dcb Energy Hub Meer 2 | H33: 310 | I33: 1.7694 | J33: 0.205 | K33: 1.5644 | L33: 484.97 | M33: =IF(K33<>"",K33,I33) -> 1.5644 | N33: =IF(K33="","n/a (no discount)",IF(ABS(I33-J33-K33)<=0.0001,"OK","CHECK")) -> OK | O33: =ROUND(M33*H33,2) -> 484.96 | P33: =O33-L33 -> -0.01 | Q33: =IF(ABS(P33)<=0.011,"OK","CHECK") -> OK
A34: 390924019 | B34: 26-05-26 | C34: 13:03 | D34: 107952 | E34: NNJ 874 | F34: Diesel | G34: Tfc Dcb Energy Hub Meer 2 | H34: 120 | I34: 1.7694 | J34: 0.205 | K34: 1.5644 | L34: 187.73 | M34: =IF(K34<>"",K34,I34) -> 1.5644 | N34: =IF(K34="","n/a (no discount)",IF(ABS(I34-J34-K34)<=0.0001,"OK","CHECK")) -> OK | O34: =ROUND(M34*H34,2) -> 187.73 | P34: =O34-L34 -> 0 | Q34: =IF(ABS(P34)<=0.011,"OK","CHECK") -> OK
A35: 390924019 | B35: 26-05-26 | C35: 13:07 | D35: 107966 | E35: NNJ 874 | F35: AdBlue | G35: Tfc Dcb Energy Hub Meer 2 | H35: 56.71 | I35: 0.6 | J35: 0 | K35: 0.6 | L35: 34.03 | M35: =IF(K35<>"",K35,I35) -> 0.6 | N35: =IF(K35="","n/a (no discount)",IF(ABS(I35-J35-K35)<=0.0001,"OK","CHECK")) -> OK | O35: =ROUND(M35*H35,2) -> 34.03 | P35: =O35-L35 -> 0 | Q35: =IF(ABS(P35)<=0.011,"OK","CHECK") -> OK
A36: 420982795 | B36: 22-05-26 | C36: 12:39 | D36: 98533 | E36: MND 992 | F36: Diesel | G36: Tfc Dcb Energy Hub Meer | H36: 120 | I36: 1.7694 | J36: 0.205 | K36: 1.5644 | L36: 187.73 | M36: =IF(K36<>"",K36,I36) -> 1.5644 | N36: =IF(K36="","n/a (no discount)",IF(ABS(I36-J36-K36)<=0.0001,"OK","CHECK")) -> OK | O36: =ROUND(M36*H36,2) -> 187.73 | P36: =O36-L36 -> 0 | Q36: =IF(ABS(P36)<=0.011,"OK","CHECK") -> OK
A37: 420982795 | B37: 22-05-26 | C37: 12:45 | D37: 98555 | E37: MND 992 | F37: Diesel | G37: Tfc Dcb Energy Hub Meer | H37: 400 | I37: 1.7694 | J37: 0.205 | K37: 1.5644 | L37: 625.76 | M37: =IF(K37<>"",K37,I37) -> 1.5644 | N37: =IF(K37="","n/a (no discount)",IF(ABS(I37-J37-K37)<=0.0001,"OK","CHECK")) -> OK | O37: =ROUND(M37*H37,2) -> 625.76 | P37: =O37-L37 -> 0 | Q37: =IF(ABS(P37)<=0.011,"OK","CHECK") -> OK
A38: 420982795 | B38: 28-05-26 | C38: 01:03 | D38: 248135 | E38: MND 992 | F38: Diesel | G38: Romac Houdeng | H38: 205.1 | I38: 1.5944 | L38: 327.02 | M38: =IF(K38<>"",K38,I38) -> 1.5944 | N38: =IF(K38="","n/a (no discount)",IF(ABS(I38-J38-K38)<=0.0001,"OK","CHECK")) -> n/a (no discount) | O38: =ROUND(M38*H38,2) -> 327.01 | P38: =O38-L38 -> -0.01 | Q38: =IF(ABS(P38)<=0.011,"OK","CHECK") -> OK
A39: 420982795 | B39: 28-05-26 | C39: 01:08 | D39: 248142 | E39: MND 992 | F39: Diesel | G39: Romac Houdeng | H39: 340 | I39: 1.5944 | L39: 542.1 | M39: =IF(K39<>"",K39,I39) -> 1.5944 | N39: =IF(K39="","n/a (no discount)",IF(ABS(I39-J39-K39)<=0.0001,"OK","CHECK")) -> n/a (no discount) | O39: =ROUND(M39*H39,2) -> 542.1 | P39: =O39-L39 -> 0 | Q39: =IF(ABS(P39)<=0.011,"OK","CHECK") -> OK
A40: 420982795 | B40: 28-05-26 | C40: 01:14 | D40: 248149 | E40: MND 992 | F40: Diesel | G40: Romac Houdeng | H40: 550 | I40: 1.5944 | L40: 876.92 | M40: =IF(K40<>"",K40,I40) -> 1.5944 | N40: =IF(K40="","n/a (no discount)",IF(ABS(I40-J40-K40)<=0.0001,"OK","CHECK")) -> n/a (no discount) | O40: =ROUND(M40*H40,2) -> 876.92 | P40: =O40-L40 -> 0 | Q40: =IF(ABS(P40)<=0.011,"OK","CHECK") -> OK
A41: 420982795 | B41: 28-05-26 | C41: 01:21 | D41: 248157 | E41: MND 992 | F41: AdBlue | G41: Romac Houdeng | H41: 78 | I41: 0.675 | L41: 52.65 | M41: =IF(K41<>"",K41,I41) -> 0.675 | N41: =IF(K41="","n/a (no discount)",IF(ABS(I41-J41-K41)<=0.0001,"OK","CHECK")) -> n/a (no discount) | O41: =ROUND(M41*H41,2) -> 52.65 | P41: =O41-L41 -> 0 | Q41: =IF(ABS(P41)<=0.011,"OK","CHECK") -> OK
A42: 431120840 | B42: 22-05-26 | C42: 13:14 | D42: 98635 | E42: MFF 264 | F42: Diesel | G42: Tfc Dcb Energy Hub Meer | H42: 354.49 | I42: 1.7694 | J42: 0.205 | K42: 1.5644 | L42: 554.57 | M42: =IF(K42<>"",K42,I42) -> 1.5644 | N42: =IF(K42="","n/a (no discount)",IF(ABS(I42-J42-K42)<=0.0001,"OK","CHECK")) -> OK | O42: =ROUND(M42*H42,2) -> 554.56 | P42: =O42-L42 -> -0.01 | Q42: =IF(ABS(P42)<=0.011,"OK","CHECK") -> OK
A43: 431120840 | B43: 22-05-26 | C43: 13:20 | D43: 98648 | E43: MFF 264 | F43: Diesel | G43: Tfc Dcb Energy Hub Meer | H43: 384.26 | I43: 1.7694 | J43: 0.205 | K43: 1.5644 | L43: 601.14 | M43: =IF(K43<>"",K43,I43) -> 1.5644 | N43: =IF(K43="","n/a (no discount)",IF(ABS(I43-J43-K43)<=0.0001,"OK","CHECK")) -> OK | O43: =ROUND(M43*H43,2) -> 601.14 | P43: =O43-L43 -> 0 | Q43: =IF(ABS(P43)<=0.011,"OK","CHECK") -> OK
A44: 431120840 | B44: 22-05-26 | C44: 13:28 | D44: 98663 | E44: MFF 264 | F44: AdBlue | G44: Tfc Dcb Energy Hub Meer | H44: 26.75 | I44: 0.6 | J44: 0 | K44: 0.6 | L44: 16.05 | M44: =IF(K44<>"",K44,I44) -> 0.6 | N44: =IF(K44="","n/a (no discount)",IF(ABS(I44-J44-K44)<=0.0001,"OK","CHECK")) -> OK | O44: =ROUND(M44*H44,2) -> 16.05 | P44: =O44-L44 -> 0 | Q44: =IF(ABS(P44)<=0.011,"OK","CHECK") -> OK
A45: 492309405 | B45: 28-05-26 | C45: 15:46 | D45: 114524 | E45: NCK 206 | F45: Diesel | G45: Tfc Dcb Energy Hub Meer 2 | H45: 235.06 | I45: 1.7694 | J45: 0.205 | K45: 1.5644 | L45: 367.73 | M45: =IF(K45<>"",K45,I45) -> 1.5644 | N45: =IF(K45="","n/a (no discount)",IF(ABS(I45-J45-K45)<=0.0001,"OK","CHECK")) -> OK | O45: =ROUND(M45*H45,2) -> 367.73 | P45: =O45-L45 -> 0 | Q45: =IF(ABS(P45)<=0.011,"OK","CHECK") -> OK
...

Sheet Card totals check
A1: Card | B1: Stated total EUR (net) | C1: Calc sum of lines | D1: Diff | E1: Check
A2: 108019237 | B2: 1537.81 | C2: =ROUND(SUMIF(Transactions!$A$2:$A$121,A2&"",Transactions!$L$2:$L$121),2) -> 1537.81 | D2: =C2-B2 -> 0 | E2: =IF(ABS(D2)<=0.01,"OK","CHECK") -> OK
A3: 145993502 | B3: 798.31 | C3: =ROUND(SUMIF(Transactions!$A$2:$A$121,A3&"",Transactions!$L$2:$L$121),2) -> 798.31 | D3: =C3-B3 -> 0 | E3: =IF(ABS(D3)<=0.01,"OK","CHECK") -> OK
A4: 168404872 | B4: 1468.9 | C4: =ROUND(SUMIF(Transactions!$A$2:$A$121,A4&"",Transactions!$L$2:$L$121),2) -> 1468.9 | D4: =C4-B4 -> 0 | E4: =IF(ABS(D4)<=0.01,"OK","CHECK") -> OK
A5: 280623763 | B5: 2234.29 | C5: =ROUND(SUMIF(Transactions!$A$2:$A$121,A5&"",Transactions!$L$2:$L$121),2) -> 2234.29 | D5: =C5-B5 -> 0 | E5: =IF(ABS(D5)<=0.01,"OK","CHECK") -> OK
A6: 332206574 | B6: 1197.69 | C6: =ROUND(SUMIF(Transactions!$A$2:$A$121,A6&"",Transactions!$L$2:$L$121),2) -> 1197.69 | D6: =C6-B6 -> 0 | E6: =IF(ABS(D6)<=0.01,"OK","CHECK") -> OK
A7: 368425169 | B7: 1622.08 | C7: =ROUND(SUMIF(Transactions!$A$2:$A$121,A7&"",Transactions!$L$2:$L$121),2) -> 1622.08 | D7: =C7-B7 -> 0 | E7: =IF(ABS(D7)<=0.01,"OK","CHECK") -> OK
A8: 390924019 | B8: 1614.09 | C8: =ROUND(SUMIF(Transactions!$A$2:$A$121,A8&"",Transactions!$L$2:$L$121),2) -> 1614.09 | D8: =C8-B8 -> 0 | E8: =IF(ABS(D8)<=0.01,"OK","CHECK") -> OK
A9: 420982795 | B9: 2612.18 | C9: =ROUND(SUMIF(Transactions!$A$2:$A$121,A9&"",Transactions!$L$2:$L$121),2) -> 2612.18 | D9: =C9-B9 -> 0 | E9: =IF(ABS(D9)<=0.01,"OK","CHECK") -> OK
A10: 431120840 | B10: 1171.76 | C10: =ROUND(SUMIF(Transactions!$A$2:$A$121,A10&"",Transactions!$L$2:$L$121),2) -> 1171.76 | D10: =C10-B10 -> 0 | E10: =IF(ABS(D10)<=0.01,"OK","CHECK") -> OK
A11: 492309405 | B11: 1480.25 | C11: =ROUND(SUMIF(Transactions!$A$2:$A$121,A11&"",Transactions!$L$2:$L$121),2) -> 1480.25 | D11: =C11-B11 -> 0 | E11: =IF(ABS(D11)<=0.01,"OK","CHECK") -> OK
A12: 496838029 | B12: 2915.68 | C12: =ROUND(SUMIF(Transactions!$A$2:$A$121,A12&"",Transactions!$L$2:$L$121),2) -> 2915.68 | D12: =C12-B12 -> 0 | E12: =IF(ABS(D12)<=0.01,"OK","CHECK") -> OK
A13: 575148137 | B13: 952.74 | C13: =ROUND(SUMIF(Transactions!$A$2:$A$121,A13&"",Transactions!$L$2:$L$121),2) -> 952.74 | D13: =C13-B13 -> 0 | E13: =IF(ABS(D13)<=0.01,"OK","CHECK") -> OK
... A27: 991011529 | B27: 1806.17 | C27: =ROUND(SUMIF(Transactions!$A$2:$A$121,A27&"",Transactions!$L$2:$L$121),2) -> 1806.17 | D27: =C27-B27 -> 0 | E27: =IF(ABS(D27)<=0.01,"OK","CHECK") -> OK
A28: TOTAL | B28: =SUM(B2:B27) -> 42454.54 | C28: =SUM(C2:C27) -> 42454.54 | D28: =C28-B28 -> 0 | E28: =IF(ABS(D28)<=0.01,"OK","CHECK") -> OK

Sheet Invoice totals check
A1: Check item | B1: Invoice states | C1: Calculated | D1: Diff | E1: Check
A2: Total excl. VAT EUR | B2: 42454.54 | C2: =ROUND(SUM(Transactions!$L$2:$L$121),2) -> 42454.54 | D2: =C2-B2 -> 0 | E2: =IF(ABS(D2)<=0.01,"OK","CHECK") -> OK
A3: VAT 21% EUR | B3: 8915.45 | C3: =ROUND(C2*0.21,2) -> 8915.45 | D3: =C3-B3 -> 0 | E3: =IF(ABS(D3)<=0.02,"OK","CHECK") -> OK
A4: Invoice total EUR | B4: 51369.99 | C4: =C2+C3 -> 51369.99 | D4: =C4-B4 -> 0 | E4: =IF(ABS(D4)<=0.03,"OK","CHECK") -> OK
A5: Diesel litres | B5: (not stated) | C5: =ROUND(SUMIF(Transactions!$F$2:$F$121,"Diesel",Transactions!$H$2:$H$121),2) -> 26754.06
A6: Diesel net EUR | B6: (not stated) | C6: =ROUND(SUMIF(Transactions!$F$2:$F$121,"Diesel",Transactions!$L$2:$L$121),2) -> 41568.74
A7: AdBlue litres | B7: (not stated) | C7: =ROUND(SUMIF(Transactions!$F$2:$F$121,"AdBlue",Transactions!$H$2:$H$121),2) -> 1429.3
A8: AdBlue net EUR | B8: (not stated) | C8: =ROUND(SUMIF(Transactions!$F$2:$F$121,"AdBlue",Transactions!$L$2:$L$121),2) -> 885.8

Sheet Station price analysis
A1: Station | B1: Diesel litres | C1: Diesel net EUR | D1: Avg eff. net EUR/L | E1: Discount shown?
A2: Tfc Dcb Energy Hub Meer | B2: =ROUND(SUMPRODUCT((Transactions!$G$2:$G$121=A2)*(Transactions!$F$2:$F$121="Diesel")*Transactions!$H$2:$H$121),2) -> 7397.92 | C2: =ROUND(SUMPRODUCT((Transactions!$G$2:$G$121=A2)*(Transactions!$F$2:$F$121="Diesel")*Transactions!$L$2:$L$121),2) -> 11335.75 | D2: =C2/B2 -> 1.5322888 | E2: yes (-0.2050)
A3: Tfc Dcb Energy Hub Meer 2 | B3: =ROUND(SUMPRODUCT((Transactions!$G$2:$G$121=A3)*(Transactions!$F$2:$F$121="Diesel")*Transactions!$H$2:$H$121),2) -> 11647.58 | C3: =ROUND(SUMPRODUCT((Transactions!$G$2:$G$121=A3)*(Transactions!$F$2:$F$121="Diesel")*Transactions!$L$2:$L$121),2) -> 18104.86 | D3: =C3/B3 -> 1.5543881 | E3: yes (-0.2050)
A4: Dcb Energy Hub Maasmechelen | B4: =ROUND(SUMPRODUCT((Transactions!$G$2:$G$121=A4)*(Transactions!$F$2:$F$121="Diesel")*Transactions!$H$2:$H$121),2) -> 3337.62 | C4: =ROUND(SUMPRODUCT((Transactions!$G$2:$G$121=A4)*(Transactions!$F$2:$F$121="Diesel")*Transactions!$L$2:$L$121),2) -> 5181.86 | D4: =C4/B4 -> 1.5525614 | E4: yes (-0.1900)
A5: Romac Houdeng | B5: =ROUND(SUMPRODUCT((Transactions!$G$2:$G$121=A5)*(Transactions!$F$2:$F$121="Diesel")*Transactions!$H$2:$H$121),2) -> 2995.91 | C5: =ROUND(SUMPRODUCT((Transactions!$G$2:$G$121=A5)*(Transactions!$F$2:$F$121="Diesel")*Transactions!$L$2:$L$121),2) -> 4776.71 | D5: =C5/B5 -> 1.5944104 | E5: no
A6: De Warande Oostkamp | B6: =ROUND(SUMPRODUCT((Transactions!$G$2:$G$121=A6)*(Transactions!$F$2:$F$121="Diesel")*Transactions!$H$2:$H$121),2) -> 635.01 | C6: =ROUND(SUMPRODUCT((Transactions!$G$2:$G$121=A6)*(Transactions!$F$2:$F$121="Diesel")*Transactions!$L$2:$L$121),2) -> 958.43 | D6: =C6/B6 -> 1.5093148 | E6: no
A7: Texaco Kruishoutem | B7: =ROUND(SUMPRODUCT((Transactions!$G$2:$G$121=A7)*(Transactions!$F$2:$F$121="Diesel")*Transactions!$H$2:$H$121),2) -> 740.02 | C7: =ROUND(SUMPRODUCT((Transactions!$G$2:$G$121=A7)*(Transactions!$F$2:$F$121="Diesel")*Transactions!$L$2:$L$121),2) -> 1211.13 | D7: =C7/B7 -> 1.6366179 | E7: no
A8: TOTAL | B8: =SUM(B2:B7) -> 26754.06 | C8: =SUM(C2:C7) -> 41568.74 | D8: =C8/B8 -> 1.5537358
